Workbook

Sheet Guia
A1: Controle de Aluguéis: guia rápido
A2: Exemplo com dados fictícios. Imóveis em Curitiba, contratos e valores inventados.
A4: Cores | B4: Texto azul = digitado. Texto verde = puxado de outra aba. Preto = fórmula. Fundo amarelo = parâmetro ou campo de escolha.
A5: Rotina do dia a dia | B5: Ao receber um aluguel, lance uma linha em Recebimentos com a data, o código da cobrança (aba Cobranças) e o valor. O resto atualiza sozinho.
A6: Situação da cobrança | B6: Calculada automaticamente: Pago, Pago com atraso, Parcial, Em atraso ou A vencer. Quando há negociação ou processo, escolha na coluna Tratativa (lista) "Em acordo" ou "Cobrança judicial"; enquanto houver saldo, a situação passa a mostrar a tratativa. Quando o saldo é quitado, volta a mostrar Pago com atraso.
A7: Faixa de atraso | B7: Cada cobrança com saldo é classificada em 1 a 30, 31 a 60, 61 a 90 ou mais de 90 dias. O Painel mostra a quantidade e o saldo de cada faixa.
A8: Cobrança judicial | B8: Lance custas, honorários e diligências na aba Cobrança judicial, indicando quem pagou e se o valor pode ser pedido ao inquilino na ação. Os custos pagos pelo proprietário são descontados no repasse. Confirme os valores reembolsáveis com o advogado responsável.
A9: Multa e juros | B9: Multa de 10% sobre o aluguel e juros de mora de 1% ao mês pro rata die (0,0333% por dia), contados do vencimento até o pagamento ou até a data de referência. Os percentuais e a tolerância ficam na aba Parâmetros e devem seguir o contrato.
A10: Correção monetária | B10: Não incluída neste exemplo. Pode ser acrescentada pelo índice do contrato (IGP-M ou IPCA).
A11: Taxa de administração | B11: 10% sobre o valor recebido, descontada no repasse junto com as despesas e os custos judiciais pagos em nome do proprietário.
A12: Repasses | B12: A aba Proprietários calcula o líquido de cada proprietário conforme a participação em cada imóvel. Lance cada transferência em Repasses e o saldo a repassar se atualiza. Saldo negativo indica que os custos superaram o recebido no período.
A13: Reajuste anual | B13: A aba Contratos calcula a data do próximo reajuste pelo aniversário do contrato e destaca os que vencem em até 60 dias.
A14: Extrato do imóvel | B14: Escolha o imóvel na célula amarela da aba Extrato: aparecem os meses, a faixa de atraso, o líquido e a divisão entre proprietários, prontos para imprimir ou enviar em PDF.
A15: Data de referência | B15: Fixada em 28/10/2026 para o exemplo. No uso real, troque por =HOJE().

Sheet Painel
A1: Painel da carteira de aluguéis
A2: Exemplo com dados fictícios. Fórmulas apenas, sem macros. Abre no Excel e no Google Sheets.
A3: Data de referência: | B3: ='Parâmetros'!$B$4
A5: Indicadores | D5: Atraso por faixa (cobranças com saldo)
A6: Aluguel vencido até a data | B6: =SUMIFS('Cobranças'!$G$5:$G$34,'Cobranças'!$F$5:$F$34,"<="&'Parâmetros'!$B$4) | D6: Faixa | E6: Cobranças | F6: Saldo (R$)
A7: Aluguel recebido (sem multa e juros) | B7: =SUM('Cobranças'!$P$5:$P$34) | D7: 1 a 30 dias | E7: =COUNTIF('Cobranças'!$R$5:$R$34,D7) | F7: =SUMIFS('Cobranças'!$N$5:$N$34,'Cobranças'!$R$5:$R$34,D7)
A8: Taxa de recebimento | B8: =IF(B6=0,0,B7/B6) | D8: 31 a 60 dias | E8: =COUNTIF('Cobranças'!$R$5:$R$34,D8) | F8: =SUMIFS('Cobranças'!$N$5:$N$34,'Cobranças'!$R$5:$R$34,D8)
A9: Em aberto (com multa e juros) | B9: =SUM('Cobranças'!$N$5:$N$34) | D9: 61 a 90 dias | E9: =COUNTIF('Cobranças'!$R$5:$R$34,D9) | F9: =SUMIFS('Cobranças'!$N$5:$N$34,'Cobranças'!$R$5:$R$34,D9)
A10: Cobranças em atraso ou parciais | B10: =COUNTIF('Cobranças'!$O$5:$O$34,"Em atraso")+COUNTIF('Cobranças'!$O$5:$O$34,"Parcial") | D10: Mais de 90 dias | E10: =COUNTIF('Cobranças'!$R$5:$R$34,D10) | F10: =SUMIFS('Cobranças'!$N$5:$N$34,'Cobranças'!$R$5:$R$34,D10)
A11: Em acordo (saldo) | B11: =SUMIFS('Cobranças'!$N$5:$N$34,'Cobranças'!$O$5:$O$34,"Em acordo") | D11: Total | E11: =SUM(E7:E10) | F11: =SUM(F7:F10)
A12: Em cobrança judicial (saldo) | B12: =SUMIFS('Cobranças'!$N$5:$N$34,'Cobranças'!$O$5:$O$34,"Cobrança judicial")
A13: Custos da cobrança judicial | B13: =SUMIFS('Cobrança judicial'!$E$5:$E$200,'Cobrança judicial'!$A$5:$A$200,"<="&'Parâmetros'!$B$4)
A14: Reajustes nos próximos 60 dias | B14: =COUNTIFS(Contratos!$J$5:$J$9,"<=60")
A15: A repassar aos proprietários | B15: ='Proprietários'!F9
A17: Por imóvel
A18: Imóvel | B18: Endereço | C18: Aluguel vencido (R$) | D18: Recebido com encargos (R$) | E18: Em aberto (R$) | F18: Taxa de adm. (R$) | G18: Despesas (R$) | H18: Custos judiciais (R$) | I18: Líquido ao proprietário (R$) | J18: Taxa de recebimento | K18: Situação
A19: ='Imóveis'!A5 | B19: ='Imóveis'!B5&" - "&'Imóveis'!C5 | C19: =SUMIFS('Cobranças'!$G$5:$G$34,'Cobranças'!$C$5:$C$34,A19,'Cobranças'!$F$5:$F$34,"<="&'Parâmetros'!$B$4) | D19: =SUMIFS('Cobranças'!$H$5:$H$34,'Cobranças'!$C$5:$C$34,A19) | E19: =SUMIFS('Cobranças'!$N$5:$N$34,'Cobranças'!$C$5:$C$34,A19) | F19: =ROUND(D19*'Parâmetros'!$B$8,2) | G19: =SUMIFS(Despesas!$D$5:$D$200,Despesas!$B$5:$B$200,A19,Despesas!$A$5:$A$200,"<="&'Parâmetros'!$B$4) | H19: =SUMIFS('Cobrança judicial'!$E$5:$E$200,'Cobrança judicial'!$B$5:$B$200,A19,'Cobrança judicial'!$F$5:$F$200,"Proprietário",'Cobrança judicial'!$A$5:$A$200,"<="&'Parâmetros'!$B$4) | I19: =D19-F19-G19-H19 | J19: =IF(C19=0,0,SUMIFS('Cobranças'!$P$5:$P$34,'Cobranças'!$C$5:$C$34,A19)/C19) | K19: =IF(COUNTIFS('Cobranças'!$C$5:$C$34,A19,'Cobranças'!$O$5:$O$34,"Cobrança judicial")>0,"Cobrança judicial",IF(COUNTIFS('Cobranças'!$C$5:$C$34,A19,'Cobranças'!$O$5:$O$34,"Em acordo")>0,"Em acordo",IF(E19>0,"Em atraso","Em dia")))
A20: ='Imóveis'!A6 | B20: ='Imóveis'!B6&" - "&'Imóveis'!C6 | C20: =SUMIFS('Cobranças'!$G$5:$G$34,'Cobranças'!$C$5:$C$34,A20,'Cobranças'!$F$5:$F$34,"<="&'Parâmetros'!$B$4) | D20: =SUMIFS('Cobranças'!$H$5:$H$34,'Cobranças'!$C$5:$C$34,A20) | E20: =SUMIFS('Cobranças'!$N$5:$N$34,'Cobranças'!$C$5:$C$34,A20) | F20: =ROUND(D20*'Parâmetros'!$B$8,2) | G20: =SUMIFS(Despesas!$D$5:$D$200,Despesas!$B$5:$B$200,A20,Despesas!$A$5:$A$200,"<="&'Parâmetros'!$B$4) | H20: =SUMIFS('Cobrança judicial'!$E$5:$E$200,'Cobrança judicial'!$B$5:$B$200,A20,'Cobrança judicial'!$F$5:$F$200,"Proprietário",'Cobrança judicial'!$A$5:$A$200,"<="&'Parâmetros'!$B$4) | I20: =D20-F20-G20-H20 | J20: =IF(C20=0,0,SUMIFS('Cobranças'!$P$5:$P$34,'Cobranças'!$C$5:$C$34,A20)/C20) | K20: =IF(COUNTIFS('Cobranças'!$C$5:$C$34,A20,'Cobranças'!$O$5:$O$34,"Cobrança judicial")>0,"Cobrança judicial",IF(COUNTIFS('Cobranças'!$C$5:$C$34,A20,'Cobranças'!$O$5:$O$34,"Em acordo")>0,"Em acordo",IF(E20>0,"Em atraso","Em dia")))
A21: ='Imóveis'!A7 | B21: ='Imóveis'!B7&" - "&'Imóveis'!C7 | C21: =SUMIFS('Cobranças'!$G$5:$G$34,'Cobranças'!$C$5:$C$34,A21,'Cobranças'!$F$5:$F$34,"<="&'Parâmetros'!$B$4) | D21: =SUMIFS('Cobranças'!$H$5:$H$34,'Cobranças'!$C$5:$C$34,A21) | E21: =SUMIFS('Cobranças'!$N$5:$N$34,'Cobranças'!$C$5:$C$34,A21) | F21: =ROUND(D21*'Parâmetros'!$B$8,2) | G21: =SUMIFS(Despesas!$D$5:$D$200,Despesas!$B$5:$B$200,A21,Despesas!$A$5:$A$200,"<="&'Parâmetros'!$B$4) | H21: =SUMIFS('Cobrança judicial'!$E$5:$E$200,'Cobrança judicial'!$B$5:$B$200,A21,'Cobrança judicial'!$F$5:$F$200,"Proprietário",'Cobrança judicial'!$A$5:$A$200,"<="&'Parâmetros'!$B$4) | I21: =D21-F21-G21-H21 | J21: =IF(C21=0,0,SUMIFS('Cobranças'!$P$5:$P$34,'Cobranças'!$C$5:$C$34,A21)/C21) | K21: =IF(COUNTIFS('Cobranças'!$C$5:$C$34,A21,'Cobranças'!$O$5:$O$34,"Cobrança judicial")>0,"Cobrança judicial",IF(COUNTIFS('Cobranças'!$C$5:$C$34,A21,'Cobranças'!$O$5:$O$34,"Em acordo")>0,"Em acordo",IF(E21>0,"Em atraso","Em dia")))
A22: ='Imóveis'!A8 | B22: ='Imóveis'!B8&" - "&'Imóveis'!C8 | C22: =SUMIFS('Cobranças'!$G$5:$G$34,'Cobranças'!$C$5:$C$34,A22,'Cobranças'!$F$5:$F$34,"<="&'Parâmetros'!$B$4) | D22: =SUMIFS('Cobranças'!$H$5:$H$34,'Cobranças'!$C$5:$C$34,A22) | E22: =SUMIFS('Cobranças'!$N$5:$N$34,'Cobranças'!$C$5:$C$34,A22) | F22: =ROUND(D22*'Parâmetros'!$B$8,2) | G22: =SUMIFS(Despesas!$D$5:$D$200,Despesas!$B$5:$B$200,A22,Despesas!$A$5:$A$200,"<="&'Parâmetros'!$B$4) | H22: =SUMIFS('Cobrança judicial'!$E$5:$E$200,'Cobrança judicial'!$B$5:$B$200,A22,'Cobrança judicial'!$F$5:$F$200,"Proprietário",'Cobrança judicial'!$A$5:$A$200,"<="&'Parâmetros'!$B$4) | I22: =D22-F22-G22-H22 | J22: =IF(C22=0,0,SUMIFS('Cobranças'!$P$5:$P$34,'Cobranças'!$C$5:$C$34,A22)/C22) | K22: =IF(COUNTIFS('Cobranças'!$C$5:$C$34,A22,'Cobranças'!$O$5:$O$34,"Cobrança judicial")>0,"Cobrança judicial",IF(COUNTIFS('Cobranças'!$C$5:$C$34,A22,'Cobranças'!$O$5:$O$34,"Em acordo")>0,"Em acordo",IF(E22>0,"Em atraso","Em dia")))
A23: ='Imóveis'!A9 | B23: ='Imóveis'!B9&" - "&'Imóveis'!C9 | C23: =SUMIFS('Cobranças'!$G$5:$G$34,'Cobranças'!$C$5:$C$34,A23,'Cobranças'!$F$5:$F$34,"<="&'Parâmetros'!$B$4) | D23: =SUMIFS('Cobranças'!$H$5:$H$34,'Cobranças'!$C$5:$C$34,A23) | E23: =SUMIFS('Cobranças'!$N$5:$N$34,'Cobranças'!$C$5:$C$34,A23) | F23: =ROUND(D23*'Parâmetros'!$B$8,2) | G23: =SUMIFS(Despesas!$D$5:$D$200,Despesas!$B$5:$B$200,A23,Despesas!$A$5:$A$200,"<="&'Parâmetros'!$B$4) | H23: =SUMIFS('Cobrança judicial'!$E$5:$E$200,'Cobrança judicial'!$B$5:$B$200,A23,'Cobrança judicial'!$F$5:$F$200,"Proprietário",'Cobrança judicial'!$A$5:$A$200,"<="&'Parâmetros'!$B$4) | I23: =D23-F23-G23-H23 | J23: =IF(C23=0,0,SUMIFS('Cobranças'!$P$5:$P$34,'Cobranças'!$C$5:$C$34,A23)/C23) | K23: =IF(COUNTIFS('Cobranças'!$C$5:$C$34,A23,'Cobranças'!$O$5:$O$34,"Cobrança judicial")>0,"Cobrança judicial",IF(COUNTIFS('Cobranças'!$C$5:$C$34,A23,'Cobranças'!$O$5:$O$34,"Em acordo")>0,"Em acordo",IF(E23>0,"Em atraso","Em dia")))
A24: Total | C24: =SUM(C19:C23) | D24: =SUM(D19:D23) | E24: =SUM(E19:E23) | F24: =SUM(F19:F23) | G24: =SUM(G19:G23) | H24: =SUM(H19:H23) | I24: =SUM(I19:I23) | J24: =IF(C24=0,0,B7/C24)
A26: Proprietários
A27: Proprietário | B27: Líquido acumulado (R$) | C27: Já repassado (R$) | D27: A repassar (R$)
A28: ='Proprietários'!A5 | B28: ='Proprietários'!D5 | C28: ='Proprietários'!E5 | D28: ='Proprietários'!F5
A29: ='Proprietários'!A6 | B29: ='Proprietários'!D6 | C29: ='Proprietários'!E6 | D29: ='Proprietários'!F6
A30: ='Proprietários'!A7 | B30: ='Proprietários'!D7 | C30: ='Proprietários'!E7 | D30: ='Proprietários'!F7

Sheet Extrato
A1: Extrato do imóvel
A2: Escolha o imóvel na célula amarela. Pronto para imprimir em uma página A4.
A4: Imóvel: | B4: I05
A5: Endereço | B5: =INDEX('Imóveis'!$B$5:$B$9,MATCH($B$4,'Imóveis'!$A$5:$A$9,0))&" - "&INDEX('Imóveis'!$C$5:$C$9,MATCH($B$4,'Imóveis'!$A$5:$A$9,0))&", Curitiba - PR"
A6: Contrato | B6: =INDEX(Contratos!$A$5:$A$9,MATCH($B$4,Contratos!$B$5:$B$9,0))
A7: Inquilino | B7: =INDEX(Contratos!$C$5:$C$9,MATCH($B$4,Contratos!$B$5:$B$9,0))
A8: Aluguel | B8: =INDEX(Contratos!$E$5:$E$9,MATCH($B$4,Contratos!$B$5:$B$9,0))
A9: Garantia | B9: =INDEX(Contratos!$H$5:$H$9,MATCH($B$4,Contratos!$B$5:$B$9,0))
A10: Próximo reajuste | B10: =INDEX(Contratos!$I$5:$I$9,MATCH($B$4,Contratos!$B$5:$B$9,0))
A11: Índice | B11: =INDEX(Contratos!$G$5:$G$9,MATCH($B$4,Contratos!$B$5:$B$9,0))
A13: Competência | B13: Vencimento | C13: Aluguel (R$) | D13: Multa (R$) | E13: Juros (R$) | F13: Recebido (R$) | G13: Saldo (R$) | H13: Situação | I13: Faixa de atraso
A14: =INDEX('Cobranças'!$E$5:$E$34,MATCH($B$4,'Cobranças'!$C$5:$C$34,0)+0) | B14: =INDEX('Cobranças'!$F$5:$F$34,MATCH($B$4,'Cobranças'!$C$5:$C$34,0)+0) | C14: =INDEX('Cobranças'!$G$5:$G$34,MATCH($B$4,'Cobranças'!$C$5:$C$34,0)+0) | D14: =INDEX('Cobranças'!$K$5:$K$34,MATCH($B$4,'Cobranças'!$C$5:$C$34,0)+0) | E14: =INDEX('Cobranças'!$L$5:$L$34,MATCH($B$4,'Cobranças'!$C$5:$C$34,0)+0) | F14: =INDEX('Cobranças'!$H$5:$H$34,MATCH($B$4,'Cobranças'!$C$5:$C$34,0)+0) | G14: =INDEX('Cobranças'!$N$5:$N$34,MATCH($B$4,'Cobranças'!$C$5:$C$34,0)+0) | H14: =INDEX('Cobranças'!$O$5:$O$34,MATCH($B$4,'Cobranças'!$C$5:$C$34,0)+0) | I14: =INDEX('Cobranças'!$R$5:$R$34,MATCH($B$4,'Cobranças'!$C$5:$C$34,0)+0)
A15: =INDEX('Cobranças'!$E$5:$E$34,MATCH($B$4,'Cobranças'!$C$5:$C$34,0)+1) | B15: =INDEX('Cobranças'!$F$5:$F$34,MATCH($B$4,'Cobranças'!$C$5:$C$34,0)+1) | C15: =INDEX('Cobranças'!$G$5:$G$34,MATCH($B$4,'Cobranças'!$C$5:$C$34,0)+1) | D15: =INDEX('Cobranças'!$K$5:$K$34,MATCH($B$4,'Cobranças'!$C$5:$C$34,0)+1) | E15: =INDEX('Cobranças'!$L$5:$L$34,MATCH($B$4,'Cobranças'!$C$5:$C$34,0)+1) | F15: =INDEX('Cobranças'!$H$5:$H$34,MATCH($B$4,'Cobranças'!$C$5:$C$34,0)+1) | G15: =INDEX('Cobranças'!$N$5:$N$34,MATCH($B$4,'Cobranças'!$C$5:$C$34,0)+1) | H15: =INDEX('Cobranças'!$O$5:$O$34,MATCH($B$4,'Cobranças'!$C$5:$C$34,0)+1) | I15: =INDEX('Cobranças'!$R$5:$R$34,MATCH($B$4,'Cobranças'!$C$5:$C$34,0)+1)
A16: =INDEX('Cobranças'!$E$5:$E$34,MATCH($B$4,'Cobranças'!$C$5:$C$34,0)+2) | B16: =INDEX('Cobranças'!$F$5:$F$34,MATCH($B$4,'Cobranças'!$C$5:$C$34,0)+2) | C16: =INDEX('Cobranças'!$G$5:$G$34,MATCH($B$4,'Cobranças'!$C$5:$C$34,0)+2) | D16: =INDEX('Cobranças'!$K$5:$K$34,MATCH($B$4,'Cobranças'!$C$5:$C$34,0)+2) | E16: =INDEX('Cobranças'!$L$5:$L$34,MATCH($B$4,'Cobranças'!$C$5:$C$34,0)+2) | F16: =INDEX('Cobranças'!$H$5:$H$34,MATCH($B$4,'Cobranças'!$C$5:$C$34,0)+2) | G16: =INDEX('Cobranças'!$N$5:$N$34,MATCH($B$4,'Cobranças'!$C$5:$C$34,0)+2) | H16: =INDEX('Cobranças'!$O$5:$O$34,MATCH($B$4,'Cobranças'!$C$5:$C$34,0)+2) | I16: =INDEX('Cobranças'!$R$5:$R$34,MATCH($B$4,'Cobranças'!$C$5:$C$34,0)+2)
A17: =INDEX('Cobranças'!$E$5:$E$34,MATCH($B$4,'Cobranças'!$C$5:$C$34,0)+3) | B17: =INDEX('Cobranças'!$F$5:$F$34,MATCH($B$4,'Cobranças'!$C$5:$C$34,0)+3) | C17: =INDEX('Cobranças'!$G$5:$G$34,MATCH($B$4,'Cobranças'!$C$5:$C$34,0)+3) | D17: =INDEX('Cobranças'!$K$5:$K$34,MATCH($B$4,'Cobranças'!$C$5:$C$34,0)+3) | E17: =INDEX('Cobranças'!$L$5:$L$34,MATCH($B$4,'Cobranças'!$C$5:$C$34,0)+3) | F17: =INDEX('Cobranças'!$H$5:$H$34,MATCH($B$4,'Cobranças'!$C$5:$C$34,0)+3) | G17: =INDEX('Cobranças'!$N$5:$N$34,MATCH($B$4,'Cobranças'!$C$5:$C$34,0)+3) | H17: =INDEX('Cobranças'!$O$5:$O$34,MATCH($B$4,'Cobranças'!$C$5:$C$34,0)+3) | I17: =INDEX('Cobranças'!$R$5:$R$34,MATCH($B$4,'Cobranças'!$C$5:$C$34,0)+3)
A18: =INDEX('Cobranças'!$E$5:$E$34,MATCH($B$4,'Cobranças'!$C$5:$C$34,0)+4) | B18: =INDEX('Cobranças'!$F$5:$F$34,MATCH($B$4,'Cobranças'!$C$5:$C$34,0)+4) | C18: =INDEX('Cobranças'!$G$5:$G$34,MATCH($B$4,'Cobranças'!$C$5:$C$34,0)+4) | D18: =INDEX('Cobranças'!$K$5:$K$34,MATCH($B$4,'Cobranças'!$C$5:$C$34,0)+4) | E18: =INDEX('Cobranças'!$L$5:$L$34,MATCH($B$4,'Cobranças'!$C$5:$C$34,0)+4) | F18: =INDEX('Cobranças'!$H$5:$H$34,MATCH($B$4,'Cobranças'!$C$5:$C$34,0)+4) | G18: =INDEX('Cobranças'!$N$5:$N$34,MATCH($B$4,'Cobranças'!$C$5:$C$34,0)+4) | H18: =INDEX('Cobranças'!$O$5:$O$34,MATCH($B$4,'Cobranças'!$C$5:$C$34,0)+4) | I18: =INDEX('Cobranças'!$R$5:$R$34,MATCH($B$4,'Cobranças'!$C$5:$C$34,0)+4)
A19: =INDEX('Cobranças'!$E$5:$E$34,MATCH($B$4,'Cobranças'!$C$5:$C$34,0)+5) | B19: =INDEX('Cobranças'!$F$5:$F$34,MATCH($B$4,'Cobranças'!$C$5:$C$34,0)+5) | C19: =INDEX('Cobranças'!$G$5:$G$34,MATCH($B$4,'Cobranças'!$C$5:$C$34,0)+5) | D19: =INDEX('Cobranças'!$K$5:$K$34,MATCH($B$4,'Cobranças'!$C$5:$C$34,0)+5) | E19: =INDEX('Cobranças'!$L$5:$L$34,MATCH($B$4,'Cobranças'!$C$5:$C$34,0)+5) | F19: =INDEX('Cobranças'!$H$5:$H$34,MATCH($B$4,'Cobranças'!$C$5:$C$34,0)+5) | G19: =INDEX('Cobranças'!$N$5:$N$34,MATCH($B$4,'Cobranças'!$C$5:$C$34,0)+5) | H19: =INDEX('Cobranças'!$O$5:$O$34,MATCH($B$4,'Cobranças'!$C$5:$C$34,0)+5) | I19: =INDEX('Cobranças'!$R$5:$R$34,MATCH($B$4,'Cobranças'!$C$5:$C$34,0)+5)
A20: Total | C20: =SUM(C14:C19) | D20: =SUM(D14:D19) | E20: =SUM(E14:E19) | F20: =SUM(F14:F19) | G20: =SUM(G14:G19)
A22: Recebido (aluguel, multa e juros) | B22: =F20
A23: (-) Taxa de administração | B23: =-ROUND(F20*'Parâmetros'!$B$8,2)
A24: (-) Despesas do proprietário | B24: =-SUMIFS(Despesas!$D$5:$D$200,Despesas!$B$5:$B$200,$B$4,Despesas!$A$5:$A$200,"<="&'Parâmetros'!$B$4)
A25: (-) Custos da cobrança judicial | B25: =-SUMIFS('Cobrança judicial'!$E$5:$E$200,'Cobrança judicial'!$B$5:$B$200,$B$4,'Cobrança judicial'!$F$5:$F$200,"Proprietário",'Cobrança judicial'!$A$5:$A$200,"<="&'Parâmetros'!$B$4)
A26: Líquido do proprietário | B26: =SUM(B22:B25)
A28: Divisão entre proprietários
A29: ='Proprietários'!A5 | B29: =INDEX('Proprietários'!$H$5:$L$5,MATCH($B$4,'Proprietários'!$H$4:$L$4,0)) | C29: =ROUND(B29*$B$26,2)
A30: ='Proprietários'!A6 | B30: =INDEX('Proprietários'!$H$6:$L$6,MATCH($B$4,'Proprietários'!$H$4:$L$4,0)) | C30: =ROUND(B30*$B$26,2)
A31: ='Proprietários'!A7 | B31: =INDEX('Proprietários'!$H$7:$L$7,MATCH($B$4,'Proprietários'!$H$4:$L$4,0)) | C31: =ROUND(B31*$B$26,2)

Sheet Recebimentos
A1: Recebimentos
A2: Lance aqui cada pagamento recebido. Use o código da cobrança (aba Cobranças).
A4: Data | B4: Cobrança | C4: Valor (R$) | D4: Forma | E4: Observação
A5: 46208 | B5: C-01 | C5: 2800 | D5: Pix
A6: 46208 | B6: C-07 | C6: 3500 | D6: Boleto
A7: 46208 | B7: C-19 | C7: 4200 | D7: Boleto
A8: 46208 | B8: C-25 | C8: 2300 | D8: Boleto
A9: 46213 | B9: C-13 | C9: 1900 | D9: Pix
A10: 46239 | B10: C-02 | C10: 2800 | D10: Pix
A11: 46239 | B11: C-08 | C11: 3500 | D11: Boleto
A12: 46239 | B12: C-20 | C12: 4200 | D12: Boleto
A13: 46244 | B13: C-14 | C13: 1900 | D13: Pix
A14: 46270 | B14: C-03 | C14: 2800 | D14: Pix
A15: 46270 | B15: C-09 | C15: 3500 | D15: Boleto
A16: 46272 | B16: C-21 | C16: 4622.8 | D16: Boleto | E16: Pago com atraso, multa e juros incluídos
A17: 46275 | B17: C-15 | C17: 1900 | D17: Pix
A18: 46300 | B18: C-04 | C18: 2800 | D18: Pix
A19: 46305 | B19: C-16 | C19: 1000 | D19: Pix | E19: Pagamento parcial; inquilino prometeu o restante
A20: 46308 | B20: C-10 | C20: 3859.33 | D20: Boleto | E20: Pago com atraso, multa e juros incluídos

Sheet Cobranças
A1: Cobranças mensais
A2: Uma linha por contrato e mês. Multa, juros, saldo, faixa de atraso e situação são calculados. A coluna Tratativa (lista) marca acordos e cobranças judiciais.
A4: Cobrança | B4: Contrato | C4: Imóvel | D4: Inquilino | E4: Competência | F4: Vencimento | G4: Aluguel (R$) | H4: Recebido (R$) | I4: Último pagamento | J4: Dias de atraso | K4: Multa (R$) | L4: Juros (R$) | M4: Total devido (R$) | N4: Saldo em aberto (R$) | O4: Situação | P4: Aluguel recebido (R$) | Q4: Tratativa | R4: Faixa de atraso | S4: Observação
A5: C-01 | B5: CT-01 | C5: =INDEX(Contratos!$B$5:$B$9,MATCH(B5,Contratos!$A$5:$A$9,0)) | D5: =INDEX(Contratos!$C$5:$C$9,MATCH(B5,Contratos!$A$5:$A$9,0)) | E5: 46204 | F5: =DATE(YEAR(E5),MONTH(E5),INDEX(Contratos!$F$5:$F$9,MATCH(B5,Contratos!$A$5:$A$9,0))) | G5: =INDEX(Contratos!$E$5:$E$9,MATCH(B5,Contratos!$A$5:$A$9,0)) | H5: =SUMIFS(Recebimentos!$C$5:$C$200,Recebimentos!$B$5:$B$200,A5) | I5: =IF(H5=0,"",_xlfn.MAXIFS(Recebimentos!$A$5:$A$200,Recebimentos!$B$5:$B$200,A5)) | J5: =IF(F5>'Parâmetros'!$B$4,0,IF(IF(I5="",FALSE,H5>=G5*(1+IF(MAX(0,I5-F5)>'Parâmetros'!$B$7,'Parâmetros'!$B$5,0))+IF(MAX(0,I5-F5)>'Parâmetros'!$B$7,G5*'Parâmetros'!$B$6/30*MAX(0,I5-F5),0)-0.01),MAX(0,I5-F5),MAX(0,'Parâmetros'!$B$4-F5))) | K5: =IF(J5>'Parâmetros'!$B$7,ROUND(G5*'Parâmetros'!$B$5,2),0) | L5: =IF(J5>'Parâmetros'!$B$7,ROUND(G5*'Parâmetros'!$B$6/30*J5,2),0) | M5: =IF(F5>'Parâmetros'!$B$4,0,G5+K5+L5) | N5: =MAX(0,ROUND(M5-H5,2)) | O5: =IF(F5>'Parâmetros'!$B$4,"A vencer",IF(N5=0,IF(J5>'Parâmetros'!$B$7,"Pago com atraso","Pago"),IF(Q5<>"",Q5,IF(H5>0,"Parcial","Em atraso")))) | P5: =IF(F5>'Parâmetros'!$B$4,0,MIN(G5,H5)) | R5: =IF(N5=0,"",IF(J5<=30,"1 a 30 dias",IF(J5<=60,"31 a 60 dias",IF(J5<=90,"61 a 90 dias","Mais de 90 dias"))))
A6: C-02 | B6: CT-01 | C6: =INDEX(Contratos!$B$5:$B$9,MATCH(B6,Contratos!$A$5:$A$9,0)) | D6: =INDEX(Contratos!$C$5:$C$9,MATCH(B6,Contratos!$A$5:$A$9,0)) | E6: 46235 | F6: =DATE(YEAR(E6),MONTH(E6),INDEX(Contratos!$F$5:$F$9,MATCH(B6,Contratos!$A$5:$A$9,0))) | G6: =INDEX(Contratos!$E$5:$E$9,MATCH(B6,Contratos!$A$5:$A$9,0)) | H6: =SUMIFS(Recebimentos!$C$5:$C$200,Recebimentos!$B$5:$B$200,A6) | I6: =IF(H6=0,"",_xlfn.MAXIFS(Recebimentos!$A$5:$A$200,Recebimentos!$B$5:$B$200,A6)) | J6: =IF(F6>'Parâmetros'!$B$4,0,IF(IF(I6="",FALSE,H6>=G6*(1+IF(MAX(0,I6-F6)>'Parâmetros'!$B$7,'Parâmetros'!$B$5,0))+IF(MAX(0,I6-F6)>'Parâmetros'!$B$7,G6*'Parâmetros'!$B$6/30*MAX(0,I6-F6),0)-0.01),MAX(0,I6-F6),MAX(0,'Parâmetros'!$B$4-F6))) | K6: =IF(J6>'Parâmetros'!$B$7,ROUND(G6*'Parâmetros'!$B$5,2),0) | L6: =IF(J6>'Parâmetros'!$B$7,ROUND(G6*'Parâmetros'!$B$6/30*J6,2),0) | M6: =IF(F6>'Parâmetros'!$B$4,0,G6+K6+L6) | N6: =MAX(0,ROUND(M6-H6,2)) | O6: =IF(F6>'Parâmetros'!$B$4,"A vencer",IF(N6=0,IF(J6>'Parâmetros'!$B$7,"Pago com atraso","Pago"),IF(Q6<>"",Q6,IF(H6>0,"Parcial","Em atraso")))) | P6: =IF(F6>'Parâmetros'!$B$4,0,MIN(G6,H6)) | R6: =IF(N6=0,"",IF(J6<=30,"1 a 30 dias",IF(J6<=60,"31 a 60 dias",IF(J6<=90,"61 a 90 dias","Mais de 90 dias"))))
A7: C-03 | B7: CT-01 | C7: =INDEX(Contratos!$B$5:$B$9,MATCH(B7,Contratos!$A$5:$A$9,0)) | D7: =INDEX(Contratos!$C$5:$C$9,MATCH(B7,Contratos!$A$5:$A$9,0)) | E7: 46266 | F7: =DATE(YEAR(E7),MONTH(E7),INDEX(Contratos!$F$5:$F$9,MATCH(B7,Contratos!$A$5:$A$9,0))) | G7: =INDEX(Contratos!$E$5:$E$9,MATCH(B7,Contratos!$A$5:$A$9,0)) | H7: =SUMIFS(Recebimentos!$C$5:$C$200,Recebimentos!$B$5:$B$200,A7) | I7: =IF(H7=0,"",_xlfn.MAXIFS(Recebimentos!$A$5:$A$200,Recebimentos!$B$5:$B$200,A7)) | J7: =IF(F7>'Parâmetros'!$B$4,0,IF(IF(I7="",FALSE,H7>=G7*(1+IF(MAX(0,I7-F7)>'Parâmetros'!$B$7,'Parâmetros'!$B$5,0))+IF(MAX(0,I7-F7)>'Parâmetros'!$B$7,G7*'Parâmetros'!$B$6/30*MAX(0,I7-F7),0)-0.01),MAX(0,I7-F7),MAX(0,'Parâmetros'!$B$4-F7))) | K7: =IF(J7>'Parâmetros'!$B$7,ROUND(G7*'Parâmetros'!$B$5,2),0) | L7: =IF(J7>'Parâmetros'!$B$7,ROUND(G7*'Parâmetros'!$B$6/30*J7,2),0) | M7: =IF(F7>'Parâmetros'!$B$4,0,G7+K7+L7) | N7: =MAX(0,ROUND(M7-H7,2)) | O7: =IF(F7>'Parâmetros'!$B$4,"A vencer",IF(N7=0,IF(J7>'Parâmetros'!$B$7,"Pago com atraso","Pago"),IF(Q7<>"",Q7,IF(H7>0,"Parcial","Em atraso")))) | P7: =IF(F7>'Parâmetros'!$B$4,0,MIN(G7,H7)) | R7: =IF(N7=0,"",IF(J7<=30,"1 a 30 dias",IF(J7<=60,"31 a 60 dias",IF(J7<=90,"61 a 90 dias","Mais de 90 dias"))))
A8: C-04 | B8: CT-01 | C8: =INDEX(Contratos!$B$5:$B$9,MATCH(B8,Contratos!$A$5:$A$9,0)) | D8: =INDEX(Contratos!$C$5:$C$9,MATCH(B8,Contratos!$A$5:$A$9,0)) | E8: 46296 | F8: =DATE(YEAR(E8),MONTH(E8),INDEX(Contratos!$F$5:$F$9,MATCH(B8,Contratos!$A$5:$A$9,0))) | G8: =INDEX(Contratos!$E$5:$E$9,MATCH(B8,Contratos!$A$5:$A$9,0)) | H8: =SUMIFS(Recebimentos!$C$5:$C$200,Recebimentos!$B$5:$B$200,A8) | I8: =IF(H8=0,"",_xlfn.MAXIFS(Recebimentos!$A$5:$A$200,Recebimentos!$B$5:$B$200,A8)) | J8: =IF(F8>'Parâmetros'!$B$4,0,IF(IF(I8="",FALSE,H8>=G8*(1+IF(MAX(0,I8-F8)>'Parâmetros'!$B$7,'Parâmetros'!$B$5,0))+IF(MAX(0,I8-F8)>'Parâmetros'!$B$7,G8*'Parâmetros'!$B$6/30*MAX(0,I8-F8),0)-0.01),MAX(0,I8-F8),MAX(0,'Parâmetros'!$B$4-F8))) | K8: =IF(J8>'Parâmetros'!$B$7,ROUND(G8*'Parâmetros'!$B$5,2),0) | L8: =IF(J8>'Parâmetros'!$B$7,ROUND(G8*'Parâmetros'!$B$6/30*J8,2),0) | M8: =IF(F8>'Parâmetros'!$B$4,0,G8+K8+L8) | N8: =MAX(0,ROUND(M8-H8,2)) | O8: =IF(F8>'Parâmetros'!$B$4,"A vencer",IF(N8=0,IF(J8>'Parâmetros'!$B$7,"Pago com atraso","Pago"),IF(Q8<>"",Q8,IF(H8>0,"Parcial","Em atraso")))) | P8: =IF(F8>'Parâmetros'!$B$4,0,MIN(G8,H8)) | R8: =IF(N8=0,"",IF(J8<=30,"1 a 30 dias",IF(J8<=60,"31 a 60 dias",IF(J8<=90,"61 a 90 dias","Mais de 90 dias"))))
A9: C-05 | B9: CT-01 | C9: =INDEX(Contratos!$B$5:$B$9,MATCH(B9,Contratos!$A$5:$A$9,0)) | D9: =INDEX(Contratos!$C$5:$C$9,MATCH(B9,Contratos!$A$5:$A$9,0)) | E9: 46327 | F9: =DATE(YEAR(E9),MONTH(E9),INDEX(Contratos!$F$5:$F$9,MATCH(B9,Contratos!$A$5:$A$9,0))) | G9: =INDEX(Contratos!$E$5:$E$9,MATCH(B9,Contratos!$A$5:$A$9,0)) | H9: =SUMIFS(Recebimentos!$C$5:$C$200,Recebimentos!$B$5:$B$200,A9) | I9: =IF(H9=0,"",_xlfn.MAXIFS(Recebimentos!$A$5:$A$200,Recebimentos!$B$5:$B$200,A9)) | J9: =IF(F9>'Parâmetros'!$B$4,0,IF(IF(I9="",FALSE,H9>=G9*(1+IF(MAX(0,I9-F9)>'Parâmetros'!$B$7,'Parâmetros'!$B$5,0))+IF(MAX(0,I9-F9)>'Parâmetros'!$B$7,G9*'Parâmetros'!$B$6/30*MAX(0,I9-F9),0)-0.01),MAX(0,I9-F9),MAX(0,'Parâmetros'!$B$4-F9))) | K9: =IF(J9>'Parâmetros'!$B$7,ROUND(G9*'Parâmetros'!$B$5,2),0) | L9: =IF(J9>'Parâmetros'!$B$7,ROUND(G9*'Parâmetros'!$B$6/30*J9,2),0) | M9: =IF(F9>'Parâmetros'!$B$4,0,G9+K9+L9) | N9: =MAX(0,ROUND(M9-H9,2)) | O9: =IF(F9>'Parâmetros'!$B$4,"A vencer",IF(N9=0,IF(J9>'Parâmetros'!$B$7,"Pago com atraso","Pago"),IF(Q9<>"",Q9,IF(H9>0,"Parcial","Em atraso")))) | P9: =IF(F9>'Parâmetros'!$B$4,0,MIN(G9,H9)) | R9: =IF(N9=0,"",IF(J9<=30,"1 a 30 dias",IF(J9<=60,"31 a 60 dias",IF(J9<=90,"61 a 90 dias","Mais de 90 dias"))))
A10: C-06 | B10: CT-01 | C10: =INDEX(Contratos!$B$5:$B$9,MATCH(B10,Contratos!$A$5:$A$9,0)) | D10: =INDEX(Contratos!$C$5:$C$9,MATCH(B10,Contratos!$A$5:$A$9,0)) | E10: 46357 | F10: =DATE(YEAR(E10),MONTH(E10),INDEX(Contratos!$F$5:$F$9,MATCH(B10,Contratos!$A$5:$A$9,0))) | G10: =INDEX(Contratos!$E$5:$E$9,MATCH(B10,Contratos!$A$5:$A$9,0)) | H10: =SUMIFS(Recebimentos!$C$5:$C$200,Recebimentos!$B$5:$B$200,A10) | I10: =IF(H10=0,"",_xlfn.MAXIFS(Recebimentos!$A$5:$A$200,Recebimentos!$B$5:$B$200,A10)) | J10: =IF(F10>'Parâmetros'!$B$4,0,IF(IF(I10="",FALSE,H10>=G10*(1+IF(MAX(0,I10-F10)>'Parâmetros'!$B$7,'Parâmetros'!$B$5,0))+IF(MAX(0,I10-F10)>'Parâmetros'!$B$7,G10*'Parâmetros'!$B$6/30*MAX(0,I10-F10),0)-0.01),MAX(0,I10-F10),MAX(0,'Parâmetros'!$B$4-F10))) | K10: =IF(J10>'Parâmetros'!$B$7,ROUND(G10*'Parâmetros'!$B$5,2),0) | L10: =IF(J10>'Parâmetros'!$B$7,ROUND(G10*'Parâmetros'!$B$6/30*J10,2),0) | M10: =IF(F10>'Parâmetros'!$B$4,0,G10+K10+L10) | N10: =MAX(0,ROUND(M10-H10,2)) | O10: =IF(F10>'Parâmetros'!$B$4,"A vencer",IF(N10=0,IF(J10>'Parâmetros'!$B$7,"Pago com atraso","Pago"),IF(Q10<>"",Q10,IF(H10>0,"Parcial","Em atraso")))) | P10: =IF(F10>'Parâmetros'!$B$4,0,MIN(G10,H10)) | R10: =IF(N10=0,"",IF(J10<=30,"1 a 30 dias",IF(J10<=60,"31 a 60 dias",IF(J10<=90,"61 a 90 dias","Mais de 90 dias"))))
A11: C-07 | B11: CT-02 | C11: =INDEX(Contratos!$B$5:$B$9,MATCH(B11,Contratos!$A$5:$A$9,0)) | D11: =INDEX(Contratos!$C$5:$C$9,MATCH(B11,Contratos!$A$5:$A$9,0)) | E11: 46204 | F11: =DATE(YEAR(E11),MONTH(E11),INDEX(Contratos!$F$5:$F$9,MATCH(B11,Contratos!$A$5:$A$9,0))) | G11: =INDEX(Contratos!$E$5:$E$9,MATCH(B11,Contratos!$A$5:$A$9,0)) | H11: =SUMIFS(Recebimentos!$C$5:$C$200,Recebimentos!$B$5:$B$200,A11) | I11: =IF(H11=0,"",_xlfn.MAXIFS(Recebimentos!$A$5:$A$200,Recebimentos!$B$5:$B$200,A11)) | J11: =IF(F11>'Parâmetros'!$B$4,0,IF(IF(I11="",FALSE,H11>=G11*(1+IF(MAX(0,I11-F11)>'Parâmetros'!$B$7,'Parâmetros'!$B$5,0))+IF(MAX(0,I11-F11)>'Parâmetros'!$B$7,G11*'Parâmetros'!$B$6/30*MAX(0,I11-F11),0)-0.01),MAX(0,I11-F11),MAX(0,'Parâmetros'!$B$4-F11))) | K11: =IF(J11>'Parâmetros'!$B$7,ROUND(G11*'Parâmetros'!$B$5,2),0) | L11: =IF(J11>'Parâmetros'!$B$7,ROUND(G11*'Parâmetros'!$B$6/30*J11,2),0) | M11: =IF(F11>'Parâmetros'!$B$4,0,G11+K11+L11) | N11: =MAX(0,ROUND(M11-H11,2)) | O11: =IF(F11>'Parâmetros'!$B$4,"A vencer",IF(N11=0,IF(J11>'Parâmetros'!$B$7,"Pago com atraso","Pago"),IF(Q11<>"",Q11,IF(H11>0,"Parcial","Em atraso")))) | P11: =IF(F11>'Parâmetros'!$B$4,0,MIN(G11,H11)) | R11: =IF(N11=0,"",IF(J11<=30,"1 a 30 dias",IF(J11<=60,"31 a 60 dias",IF(J11<=90,"61 a 90 dias","Mais de 90 dias"))))
A12: C-08 | B12: CT-02 | C12: =INDEX(Contratos!$B$5:$B$9,MATCH(B12,Contratos!$A$5:$A$9,0)) | D12: =INDEX(Contratos!$C$5:$C$9,MATCH(B12,Contratos!$A$5:$A$9,0)) | E12: 46235 | F12: =DATE(YEAR(E12),MONTH(E12),INDEX(Contratos!$F$5:$F$9,MATCH(B12,Contratos!$A$5:$A$9,0))) | G12: =INDEX(Contratos!$E$5:$E$9,MATCH(B12,Contratos!$A$5:$A$9,0)) | H12: =SUMIFS(Recebimentos!$C$5:$C$200,Recebimentos!$B$5:$B$200,A12) | I12: =IF(H12=0,"",_xlfn.MAXIFS(Recebimentos!$A$5:$A$200,Recebimentos!$B$5:$B$200,A12)) | J12: =IF(F12>'Parâmetros'!$B$4,0,IF(IF(I12="",FALSE,H12>=G12*(1+IF(MAX(0,I12-F12)>'Parâmetros'!$B$7,'Parâmetros'!$B$5,0))+IF(MAX(0,I12-F12)>'Parâmetros'!$B$7,G12*'Parâmetros'!$B$6/30*MAX(0,I12-F12),0)-0.01),MAX(0,I12-F12),MAX(0,'Parâmetros'!$B$4-F12))) | K12: =IF(J12>'Parâmetros'!$B$7,ROUND(G12*'Parâmetros'!$B$5,2),0) | L12: =IF(J12>'Parâmetros'!$B$7,ROUND(G12*'Parâmetros'!$B$6/30*J12,2),0) | M12: =IF(F12>'Parâmetros'!$B$4,0,G12+K12+L12) | N12: =MAX(0,ROUND(M12-H12,2)) | O12: =IF(F12>'Parâmetros'!$B$4,"A vencer",IF(N12=0,IF(J12>'Parâmetros'!$B$7,"Pago com atraso","Pago"),IF(Q12<>"",Q12,IF(H12>0,"Parcial","Em atraso")))) | P12: =IF(F12>'Parâmetros'!$B$4,0,MIN(G12,H12)) | R12: =IF(N12=0,"",IF(J12<=30,"1 a 30 dias",IF(J12<=60,"31 a 60 dias",IF(J12<=90,"61 a 90 dias","Mais de 90 dias"))))
A13: C-09 | B13: CT-02 | C13: =INDEX(Contratos!$B$5:$B$9,MATCH(B13,Contratos!$A$5:$A$9,0)) | D13: =INDEX(Contratos!$C$5:$C$9,MATCH(B13,Contratos!$A$5:$A$9,0)) | E13: 46266 | F13: =DATE(YEAR(E13),MONTH(E13),INDEX(Contratos!$F$5:$F$9,MATCH(B13,Contratos!$A$5:$A$9,0))) | G13: =INDEX(Contratos!$E$5:$E$9,MATCH(B13,Contratos!$A$5:$A$9,0)) | H13: =SUMIFS(Recebimentos!$C$5:$C$200,Recebimentos!$B$5:$B$200,A13) | I13: =IF(H13=0,"",_xlfn.MAXIFS(Recebimentos!$A$5:$A$200,Recebimentos!$B$5:$B$200,A13)) | J13: =IF(F13>'Parâmetros'!$B$4,0,IF(IF(I13="",FALSE,H13>=G13*(1+IF(MAX(0,I13-F13)>'Parâmetros'!$B$7,'Parâmetros'!$B$5,0))+IF(MAX(0,I13-F13)>'Parâmetros'!$B$7,G13*'Parâmetros'!$B$6/30*MAX(0,I13-F13),0)-0.01),MAX(0,I13-F13),MAX(0,'Parâmetros'!$B$4-F13))) | K13: =IF(J13>'Parâmetros'!$B$7,ROUND(G13*'Parâmetros'!$B$5,2),0) | L13: =IF(J13>'Parâmetros'!$B$7,ROUND(G13*'Parâmetros'!$B$6/30*J13,2),0) | M13: =IF(F13>'Parâmetros'!$B$4,0,G13+K13+L13) | N13: =MAX(0,ROUND(M13-H13,2)) | O13: =IF(F13>'Parâmetros'!$B$4,"A vencer",IF(N13=0,IF(J13>'Parâmetros'!$B$7,"Pago com atraso","Pago"),IF(Q13<>"",Q13,IF(H13>0,"Parcial","Em atraso")))) | P13: =IF(F13>'Parâmetros'!$B$4,0,MIN(G13,H13)) | R13: =IF(N13=0,"",IF(J13<=30,"1 a 30 dias",IF(J13<=60,"31 a 60 dias",IF(J13<=90,"61 a 90 dias","Mais de 90 dias"))))
A14: C-10 | B14: CT-02 | C14: =INDEX(Contratos!$B$5:$B$9,MATCH(B14,Contratos!$A$5:$A$9,0)) | D14: =INDEX(Contratos!$C$5:$C$9,MATCH(B14,Contratos!$A$5:$A$9,0)) | E14: 46296 | F14: =DATE(YEAR(E14),MONTH(E14),INDEX(Contratos!$F$5:$F$9,MATCH(B14,Contratos!$A$5:$A$9,0))) | G14: =INDEX(Contratos!$E$5:$E$9,MATCH(B14,Contratos!$A$5:$A$9,0)) | H14: =SUMIFS(Recebimentos!$C$5:$C$200,Recebimentos!$B$5:$B$200,A14) | I14: =IF(H14=0,"",_xlfn.MAXIFS(Recebimentos!$A$5:$A$200,Recebimentos!$B$5:$B$200,A14)) | J14: =IF(F14>'Parâmetros'!$B$4,0,IF(IF(I14="",FALSE,H14>=G14*(1+IF(MAX(0,I14-F14)>'Parâmetros'!$B$7,'Parâmetros'!$B$5,0))+IF(MAX(0,I14-F14)>'Parâmetros'!$B$7,G14*'Parâmetros'!$B$6/30*MAX(0,I14-F14),0)-0.01),MAX(0,I14-F14),MAX(0,'Parâmetros'!$B$4-F14))) | K14: =IF(J14>'Parâmetros'!$B$7,ROUND(G14*'Parâmetros'!$B$5,2),0) | L14: =IF(J14>'Parâmetros'!$B$7,ROUND(G14*'Parâmetros'!$B$6/30*J14,2),0) | M14: =IF(F14>'Parâmetros'!$B$4,0,G14+K14+L14) | N14: =MAX(0,ROUND(M14-H14,2)) | O14: =IF(F14>'Parâmetros'!$B$4,"A vencer",IF(N14=0,IF(J14>'Parâmetros'!$B$7,"Pago com atraso","Pago"),IF(Q14<>"",Q14,IF(H14>0,"Parcial","Em atraso")))) | P14: =IF(F14>'Parâmetros'!$B$4,0,MIN(G14,H14)) | R14: =IF(N14=0,"",IF(J14<=30,"1 a 30 dias",IF(J14<=60,"31 a 60 dias",IF(J14<=90,"61 a 90 dias","Mais de 90 dias"))))
A15: C-11 | B15: CT-02 | C15: =INDEX(Contratos!$B$5:$B$9,MATCH(B15,Contratos!$A$5:$A$9,0)) | D15: =INDEX(Contratos!$C$5:$C$9,MATCH(B15,Contratos!$A$5:$A$9,0)) | E15: 46327 | F15: =DATE(YEAR(E15),MONTH(E15),INDEX(Contratos!$F$5:$F$9,MATCH(B15,Contratos!$A$5:$A$9,0))) | G15: =INDEX(Contratos!$E$5:$E$9,MATCH(B15,Contratos!$A$5:$A$9,0)) | H15: =SUMIFS(Recebimentos!$C$5:$C$200,Recebimentos!$B$5:$B$200,A15) | I15: =IF(H15=0,"",_xlfn.MAXIFS(Recebimentos!$A$5:$A$200,Recebimentos!$B$5:$B$200,A15)) | J15: =IF(F15>'Parâmetros'!$B$4,0,IF(IF(I15="",FALSE,H15>=G15*(1+IF(MAX(0,I15-F15)>'Parâmetros'!$B$7,'Parâmetros'!$B$5,0))+IF(MAX(0,I15-F15)>'Parâmetros'!$B$7,G15*'Parâmetros'!$B$6/30*MAX(0,I15-F15),0)-0.01),MAX(0,I15-F15),MAX(0,'Parâmetros'!$B$4-F15))) | K15: =IF(J15>'Parâmetros'!$B$7,ROUND(G15*'Parâmetros'!$B$5,2),0) | L15: =IF(J15>'Parâmetros'!$B$7,ROUND(G15*'Parâmetros'!$B$6/30*J15,2),0) | M15: =IF(F15>'Parâmetros'!$B$4,0,G15+K15+L15) | N15: =MAX(0,ROUND(M15-H15,2)) | O15: =IF(F15>'Parâmetros'!$B$4,"A vencer",IF(N15=0,IF(J15>'Parâmetros'!$B$7,"Pago com atraso","Pago"),IF(Q15<>"",Q15,IF(H15>0,"Parcial","Em atraso")))) | P15: =IF(F15>'Parâmetros'!$B$4,0,MIN(G15,H15)) | R15: =IF(N15=0,"",IF(J15<=30,"1 a 30 dias",IF(J15<=60,"31 a 60 dias",IF(J15<=90,"61 a 90 dias","Mais de 90 dias"))))
A16: C-12 | B16: CT-02 | C16: =INDEX(Contratos!$B$5:$B$9,MATCH(B16,Contratos!$A$5:$A$9,0)) | D16: =INDEX(Contratos!$C$5:$C$9,MATCH(B16,Contratos!$A$5:$A$9,0)) | E16: 46357 | F16: =DATE(YEAR(E16),MONTH(E16),INDEX(Contratos!$F$5:$F$9,MATCH(B16,Contratos!$A$5:$A$9,0))) | G16: =INDEX(Contratos!$E$5:$E$9,MATCH(B16,Contratos!$A$5:$A$9,0)) | H16: =SUMIFS(Recebimentos!$C$5:$C$200,Recebimentos!$B$5:$B$200,A16) | I16: =IF(H16=0,"",_xlfn.MAXIFS(Recebimentos!$A$5:$A$200,Recebimentos!$B$5:$B$200,A16)) | J16: =IF(F16>'Parâmetros'!$B$4,0,IF(IF(I16="",FALSE,H16>=G16*(1+IF(MAX(0,I16-F16)>'Parâmetros'!$B$7,'Parâmetros'!$B$5,0))+IF(MAX(0,I16-F16)>'Parâmetros'!$B$7,G16*'Parâmetros'!$B$6/30*MAX(0,I16-F16),0)-0.01),MAX(0,I16-F16),MAX(0,'Parâmetros'!$B$4-F16))) | K16: =IF(J16>'Parâmetros'!$B$7,ROUND(G16*'Parâmetros'!$B$5,2),0) | L16: =IF(J16>'Parâmetros'!$B$7,ROUND(G16*'Parâmetros'!$B$6/30*J16,2),0) | M16: =IF(F16>'Parâmetros'!$B$4,0,G16+K16+L16) | N16: =MAX(0,ROUND(M16-H16,2)) | O16: =IF(F16>'Parâmetros'!$B$4,"A vencer",IF(N16=0,IF(J16>'Parâmetros'!$B$7,"Pago com atraso","Pago"),IF(Q16<>"",Q16,IF(H16>0,"Parcial","Em atraso")))) | P16: =IF(F16>'Parâmetros'!$B$4,0,MIN(G16,H16)) | R16: =IF(N16=0,"",IF(J16<=30,"1 a 30 dias",IF(J16<=60,"31 a 60 dias",IF(J16<=90,"61 a 90 dias","Mais de 90 dias"))))
... A19: C-15 | B19: CT-03 | C19: =INDEX(Contratos!$B$5:$B$9,MATCH(B19,Contratos!$A$5:$A$9,0)) | D19: =INDEX(Contratos!$C$5:$C$9,MATCH(B19,Contratos!$A$5:$A$9,0)) | E19: 46266 | F19: =DATE(YEAR(E19),MONTH(E19),INDEX(Contratos!$F$5:$F$9,MATCH(B19,Contratos!$A$5:$A$9,0))) | G19: =INDEX(Contratos!$E$5:$E$9,MATCH(B19,Contratos!$A$5:$A$9,0)) | H19: =SUMIFS(Recebimentos!$C$5:$C$200,Recebimentos!$B$5:$B$200,A19) | I19: =IF(H19=0,"",_xlfn.MAXIFS(Recebimentos!$A$5:$A$200,Recebimentos!$B$5:$B$200,A19)) | J19: =IF(F19>'Parâmetros'!$B$4,0,IF(IF(I19="",FALSE,H19>=G19*(1+IF(MAX(0,I19-F19)>'Parâmetros'!$B$7,'Parâmetros'!$B$5,0))+IF(MAX(0,I19-F19)>'Parâmetros'!$B$7,G19*'Parâmetros'!$B$6/30*MAX(0,I19-F19),0)-0.01),MAX(0,I19-F19),MAX(0,'Parâmetros'!$B$4-F19))) | K19: =IF(J19>'Parâmetros'!$B$7,ROUND(G19*'Parâmetros'!$B$5,2),0) | L19: =IF(J19>'Parâmetros'!$B$7,ROUND(G19*'Parâmetros'!$B$6/30*J19,2),0) | M19: =IF(F19>'Parâmetros'!$B$4,0,G19+K19+L19) | N19: =MAX(0,ROUND(M19-H19,2)) | O19: =IF(F19>'Parâmetros'!$B$4,"A vencer",IF(N19=0,IF(J19>'Parâmetros'!$B$7,"Pago com atraso","Pago"),IF(Q19<>"",Q19,IF(H19>0,"Parcial","Em atraso")))) | P19: =IF(F19>'Parâmetros'!$B$4,0,MIN(G19,H19)) | R19: =IF(N19=0,"",IF(J19<=30,"1 a 30 dias",IF(J19<=60,"31 a 60 dias",IF(J19<=90,"61 a 90 dias","Mais de 90 dias"))))
A20: C-16 | B20: CT-03 | C20: =INDEX(Contratos!$B$5:$B$9,MATCH(B20,Contratos!$A$5:$A$9,0)) | D20: =INDEX(Contratos!$C$5:$C$9,MATCH(B20,Contratos!$A$5:$A$9,0)) | E20: 46296 | F20: =DATE(YEAR(E20),MONTH(E20),INDEX(Contratos!$F$5:$F$9,MATCH(B20,Contratos!$A$5:$A$9,0))) | G20: =INDEX(Contratos!$E$5:$E$9,MATCH(B20,Contratos!$A$5:$A$9,0)) | H20: =SUMIFS(Recebimentos!$C$5:$C$200,Recebimentos!$B$5:$B$200,A20) | I20: =IF(H20=0,"",_xlfn.MAXIFS(Recebimentos!$A$5:$A$200,Recebimentos!$B$5:$B$200,A20)) | J20: =IF(F20>'Parâmetros'!$B$4,0,IF(IF(I20="",FALSE,H20>=G20*(1+IF(MAX(0,I20-F20)>'Parâmetros'!$B$7,'Parâmetros'!$B$5,0))+IF(MAX(0,I20-F20)>'Parâmetros'!$B$7,G20*'Parâmetros'!$B$6/30*MAX(0,I20-F20),0)-0.01),MAX(0,I20-F20),MAX(0,'Parâmetros'!$B$4-F20))) | K20: =IF(J20>'Parâmetros'!$B$7,ROUND(G20*'Parâmetros'!$B$5,2),0) | L20: =IF(J20>'Parâmetros'!$B$7,ROUND(G20*'Parâmetros'!$B$6/30*J20,2),0) | M20: =IF(F20>'Parâmetros'!$B$4,0,G20+K20+L20) | N20: =MAX(0,ROUND(M20-H20,2)) | O20: =IF(F20>'Parâmetros'!$B$4,"A vencer",IF(N20=0,IF(J20>'Parâmetros'!$B$7,"Pago com atraso","Pago"),IF(Q20<>"",Q20,IF(H20>0,"Parcial","Em atraso")))) | P20: =IF(F20>'Parâmetros'!$B$4,0,MIN(G20,H20)) | Q20: Em acordo | R20: =IF(N20=0,"",IF(J20<=30,"1 a 30 dias",IF(J20<=60,"31 a 60 dias",IF(J20<=90,"61 a 90 dias","Mais de 90 dias")))) | S20: Acordo em 15/10: restante com multa e juros até 10/11/2026
A21: C-17 | B21: CT-03 | C21: =INDEX(Contratos!$B$5:$B$9,MATCH(B21,Contratos!$A$5:$A$9,0)) | D21: =INDEX(Contratos!$C$5:$C$9,MATCH(B21,Contratos!$A$5:$A$9,0)) | E21: 46327 | F21: =DATE(YEAR(E21),MONTH(E21),INDEX(Contratos!$F$5:$F$9,MATCH(B21,Contratos!$A$5:$A$9,0))) | G21: =INDEX(Contratos!$E$5:$E$9,MATCH(B21,Contratos!$A$5:$A$9,0)) | H21: =SUMIFS(Recebimentos!$C$5:$C$200,Recebimentos!$B$5:$B$200,A21) | I21: =IF(H21=0,"",_xlfn.MAXIFS(Recebimentos!$A$5:$A$200,Recebimentos!$B$5:$B$200,A21)) | J21: =IF(F21>'Parâmetros'!$B$4,0,IF(IF(I21="",FALSE,H21>=G21*(1+IF(MAX(0,I21-F21)>'Parâmetros'!$B$7,'Parâmetros'!$B$5,0))+IF(MAX(0,I21-F21)>'Parâmetros'!$B$7,G21*'Parâmetros'!$B$6/30*MAX(0,I21-F21),0)-0.01),MAX(0,I21-F21),MAX(0,'Parâmetros'!$B$4-F21))) | K21: =IF(J21>'Parâmetros'!$B$7,ROUND(G21*'Parâmetros'!$B$5,2),0) | L21: =IF(J21>'Parâmetros'!$B$7,ROUND(G21*'Parâmetros'!$B$6/30*J21,2),0) | M21: =IF(F21>'Parâmetros'!$B$4,0,G21+K21+L21) | N21: =MAX(0,ROUND(M21-H21,2)) | O21: =IF(F21>'Parâmetros'!$B$4,"A vencer",IF(N21=0,IF(J21>'Parâmetros'!$B$7,"Pago com atraso","Pago"),IF(Q21<>"",Q21,IF(H21>0,"Parcial","Em atraso")))) | P21: =IF(F21>'Parâmetros'!$B$4,0,MIN(G21,H21)) | R21: =IF(N21=0,"",IF(J21<=30,"1 a 30 dias",IF(J21<=60,"31 a 60 dias",IF(J21<=90,"61 a 90 dias","Mais de 90 dias"))))
A22: C-18 | B22: CT-03 | C22: =INDEX(Contratos!$B$5:$B$9,MATCH(B22,Contratos!$A$5:$A$9,0)) | D22: =INDEX(Contratos!$C$5:$C$9,MATCH(B22,Contratos!$A$5:$A$9,0)) | E22: 46357 | F22: =DATE(YEAR(E22),MONTH(E22),INDEX(Contratos!$F$5:$F$9,MATCH(B22,Contratos!$A$5:$A$9,0))) | G22: =INDEX(Contratos!$E$5:$E$9,MATCH(B22,Contratos!$A$5:$A$9,0)) | H22: =SUMIFS(Recebimentos!$C$5:$C$200,Recebimentos!$B$5:$B$200,A22) | I22: =IF(H22=0,"",_xlfn.MAXIFS(Recebimentos!$A$5:$A$200,Recebimentos!$B$5:$B$200,A22)) | J22: =IF(F22>'Parâmetros'!$B$4,0,IF(IF(I22="",FALSE,H22>=G22*(1+IF(MAX(0,I22-F22)>'Parâmetros'!$B$7,'Parâmetros'!$B$5,0))+IF(MAX(0,I22-F22)>'Parâmetros'!$B$7,G22*'Parâmetros'!$B$6/30*MAX(0,I22-F22),0)-0.01),MAX(0,I22-F22),MAX(0,'Parâmetros'!$B$4-F22))) | K22: =IF(J22>'Parâmetros'!$B$7,ROUND(G22*'Parâmetros'!$B$5,2),0) | L22: =IF(J22>'Parâmetros'!$B$7,ROUND(G22*'Parâmetros'!$B$6/30*J22,2),0) | M22: =IF(F22>'Parâmetros'!$B$4,0,G22+K22+L22) | N22: =MAX(0,ROUND(M22-H22,2)) | O22: =IF(F22>'Parâmetros'!$B$4,"A vencer",IF(N22=0,IF(J22>'Parâmetros'!$B$7,"Pago com atraso","Pago"),IF(Q22<>"",Q22,IF(H22>0,"Parcial","Em atraso")))) | P22: =IF(F22>'Parâmetros'!$B$4,0,MIN(G22,H22)) | R22: =IF(N22=0,"",IF(J22<=30,"1 a 30 dias",IF(J22<=60,"31 a 60 dias",IF(J22<=90,"61 a 90 dias","Mais de 90 dias"))))
A23: C-19 | B23: CT-04 | C23: =INDEX(Contratos!$B$5:$B$9,MATCH(B23,Contratos!$A$5:$A$9,0)) | D23: =INDEX(Contratos!$C$5:$C$9,MATCH(B23,Contratos!$A$5:$A$9,0)) | E23: 46204 | F23: =DATE(YEAR(E23),MONTH(E23),INDEX(Contratos!$F$5:$F$9,MATCH(B23,Contratos!$A$5:$A$9,0))) | G23: =INDEX(Contratos!$E$5:$E$9,MATCH(B23,Contratos!$A$5:$A$9,0)) | H23: =SUMIFS(Recebimentos!$C$5:$C$200,Recebimentos!$B$5:$B$200,A23) | I23: =IF(H23=0,"",_xlfn.MAXIFS(Recebimentos!$A$5:$A$200,Recebimentos!$B$5:$B$200,A23)) | J23: =IF(F23>'Parâmetros'!$B$4,0,IF(IF(I23="",FALSE,H23>=G23*(1+IF(MAX(0,I23-F23)>'Parâmetros'!$B$7,'Parâmetros'!$B$5,0))+IF(MAX(0,I23-F23)>'Parâmetros'!$B$7,G23*'Parâmetros'!$B$6/30*MAX(0,I23-F23),0)-0.01),MAX(0,I23-F23),MAX(0,'Parâmetros'!$B$4-F23))) | K23: =IF(J23>'Parâmetros'!$B$7,ROUND(G23*'Parâmetros'!$B$5,2),0) | L23: =IF(J23>'Parâmetros'!$B$7,ROUND(G23*'Parâmetros'!$B$6/30*J23,2),0) | M23: =IF(F23>'Parâmetros'!$B$4,0,G23+K23+L23) | N23: =MAX(0,ROUND(M23-H23,2)) | O23: =IF(F23>'Parâmetros'!$B$4,"A vencer",IF(N23=0,IF(J23>'Parâmetros'!$B$7,"Pago com atraso","Pago"),IF(Q23<>"",Q23,IF(H23>0,"Parcial","Em atraso")))) | P23: =IF(F23>'Parâmetros'!$B$4,0,MIN(G23,H23)) | R23: =IF(N23=0,"",IF(J23<=30,"1 a 30 dias",IF(J23<=60,"31 a 60 dias",IF(J23<=90,"61 a 90 dias","Mais de 90 dias"))))
A24: C-20 | B24: CT-04 | C24: =INDEX(Contratos!$B$5:$B$9,MATCH(B24,Contratos!$A$5:$A$9,0)) | D24: =INDEX(Contratos!$C$5:$C$9,MATCH(B24,Contratos!$A$5:$A$9,0)) | E24: 46235 | F24: =DATE(YEAR(E24),MONTH(E24),INDEX(Contratos!$F$5:$F$9,MATCH(B24,Contratos!$A$5:$A$9,0))) | G24: =INDEX(Contratos!$E$5:$E$9,MATCH(B24,Contratos!$A$5:$A$9,0)) | H24: =SUMIFS(Recebimentos!$C$5:$C$200,Recebimentos!$B$5:$B$200,A24) | I24: =IF(H24=0,"",_xlfn.MAXIFS(Recebimentos!$A$5:$A$200,Recebimentos!$B$5:$B$200,A24)) | J24: =IF(F24>'Parâmetros'!$B$4,0,IF(IF(I24="",FALSE,H24>=G24*(1+IF(MAX(0,I24-F24)>'Parâmetros'!$B$7,'Parâmetros'!$B$5,0))+IF(MAX(0,I24-F24)>'Parâmetros'!$B$7,G24*'Parâmetros'!$B$6/30*MAX(0,I24-F24),0)-0.01),MAX(0,I24-F24),MAX(0,'Parâmetros'!$B$4-F24))) | K24: =IF(J24>'Parâmetros'!$B$7,ROUND(G24*'Parâmetros'!$B$5,2),0) | L24: =IF(J24>'Parâmetros'!$B$7,ROUND(G24*'Parâmetros'!$B$6/30*J24,2),0) | M24: =IF(F24>'Parâmetros'!$B$4,0,G24+K24+L24) | N24: =MAX(0,ROUND(M24-H24,2)) | O24: =IF(F24>'Parâmetros'!$B$4,"A vencer",IF(N24=0,IF(J24>'Parâmetros'!$B$7,"Pago com atraso","Pago"),IF(Q24<>"",Q24,IF(H24>0,"Parcial","Em atraso")))) | P24: =IF(F24>'Parâmetros'!$B$4,0,MIN(G24,H24)) | R24: =IF(N24=0,"",IF(J24<=30,"1 a 30 dias",IF(J24<=60,"31 a 60 dias",IF(J24<=90,"61 a 90 dias","Mais de 90 dias"))))
A25: C-21 | B25: CT-04 | C25: =INDEX(Contratos!$B$5:$B$9,MATCH(B25,Contratos!$A$5:$A$9,0)) | D25: =INDEX(Contratos!$C$5:$C$9,MATCH(B25,Contratos!$A$5:$A$9,0)) | E25: 46266 | F25: =DATE(YEAR(E25),MONTH(E25),INDEX(Contratos!$F$5:$F$9,MATCH(B25,Contratos!$A$5:$A$9,0))) | G25: =INDEX(Contratos!$E$5:$E$9,MATCH(B25,Contratos!$A$5:$A$9,0)) | H25: =SUMIFS(Recebimentos!$C$5:$C$200,Recebimentos!$B$5:$B$200,A25) | I25: =IF(H25=0,"",_xlfn.MAXIFS(Recebimentos!$A$5:$A$200,Recebimentos!$B$5:$B$200,A25)) | J25: =IF(F25>'Parâmetros'!$B$4,0,IF(IF(I25="",FALSE,H25>=G25*(1+IF(MAX(0,I25-F25)>'Parâmetros'!$B$7,'Parâmetros'!$B$5,0))+IF(MAX(0,I25-F25)>'Parâmetros'!$B$7,G25*'Parâmetros'!$B$6/30*MAX(0,I25-F25),0)-0.01),MAX(0,I25-F25),MAX(0,'Parâmetros'!$B$4-F25))) | K25: =IF(J25>'Parâmetros'!$B$7,ROUND(G25*'Parâmetros'!$B$5,2),0) | L25: =IF(J25>'Parâmetros'!$B$7,ROUND(G25*'Parâmetros'!$B$6/30*J25,2),0) | M25: =IF(F25>'Parâmetros'!$B$4,0,G25+K25+L25) | N25: =MAX(0,ROUND(M25-H25,2)) | O25: =IF(F25>'Parâmetros'!$B$4,"A vencer",IF(N25=0,IF(J25>'Parâmetros'!$B$7,"Pago com atraso","Pago"),IF(Q25<>"",Q25,IF(H25>0,"Parcial","Em atraso")))) | P25: =IF(F25>'Parâmetros'!$B$4,0,MIN(G25,H25)) | R25: =IF(N25=0,"",IF(J25<=30,"1 a 30 dias",IF(J25<=60,"31 a 60 dias",IF(J25<=90,"61 a 90 dias","Mais de 90 dias"))))
A26: C-22 | B26: CT-04 | C26: =INDEX(Contratos!$B$5:$B$9,MATCH(B26,Contratos!$A$5:$A$9,0)) | D26: =INDEX(Contratos!$C$5:$C$9,MATCH(B26,Contratos!$A$5:$A$9,0)) | E26: 46296 | F26: =DATE(YEAR(E26),MONTH(E26),INDEX(Contratos!$F$5:$F$9,MATCH(B26,Contratos!$A$5:$A$9,0))) | G26: =INDEX(Contratos!$E$5:$E$9,MATCH(B26,Contratos!$A$5:$A$9,0)) | H26: =SUMIFS(Recebimentos!$C$5:$C$200,Recebimentos!$B$5:$B$200,A26) | I26: =IF(H26=0,"",_xlfn.MAXIFS(Recebimentos!$A$5:$A$200,Recebimentos!$B$5:$B$200,A26)) | J26: =IF(F26>'Parâmetros'!$B$4,0,IF(IF(I26="",FALSE,H26>=G26*(1+IF(MAX(0,I26-F26)>'Parâmetros'!$B$7,'Parâmetros'!$B$5,0))+IF(MAX(0,I26-F26)>'Parâmetros'!$B$7,G26*'Parâmetros'!$B$6/30*MAX(0,I26-F26),0)-0.01),MAX(0,I26-F26),MAX(0,'Parâmetros'!$B$4-F26))) | K26: =IF(J26>'Parâmetros'!$B$7,ROUND(G26*'Parâmetros'!$B$5,2),0) | L26: =IF(J26>'Parâmetros'!$B$7,ROUND(G26*'Parâmetros'!$B$6/30*J26,2),0) | M26: =IF(F26>'Parâmetros'!$B$4,0,G26+K26+L26) | N26: =MAX(0,ROUND(M26-H26,2)) | O26: =IF(F26>'Parâmetros'!$B$4,"A vencer",IF(N26=0,IF(J26>'Parâmetros'!$B$7,"Pago com atraso","Pago"),IF(Q26<>"",Q26,IF(H26>0,"Parcial","Em atraso")))) | P26: =IF(F26>'Parâmetros'!$B$4,0,MIN(G26,H26)) | R26: =IF(N26=0,"",IF(J26<=30,"1 a 30 dias",IF(J26<=60,"31 a 60 dias",IF(J26<=90,"61 a 90 dias","Mais de 90 dias"))))
A27: C-23 | B27: CT-04 | C27: =INDEX(Contratos!$B$5:$B$9,MATCH(B27,Contratos!$A$5:$A$9,0)) | D27: =INDEX(Contratos!$C$5:$C$9,MATCH(B27,Contratos!$A$5:$A$9,0)) | E27: 46327 | F27: =DATE(YEAR(E27),MONTH(E27),INDEX(Contratos!$F$5:$F$9,MATCH(B27,Contratos!$A$5:$A$9,0))) | G27: =INDEX(Contratos!$E$5:$E$9,MATCH(B27,Contratos!$A$5:$A$9,0)) | H27: =SUMIFS(Recebimentos!$C$5:$C$200,Recebimentos!$B$5:$B$200,A27) | I27: =IF(H27=0,"",_xlfn.MAXIFS(Recebimentos!$A$5:$A$200,Recebimentos!$B$5:$B$200,A27)) | J27: =IF(F27>'Parâmetros'!$B$4,0,IF(IF(I27="",FALSE,H27>=G27*(1+IF(MAX(0,I27-F27)>'Parâmetros'!$B$7,'Parâmetros'!$B$5,0))+IF(MAX(0,I27-F27)>'Parâmetros'!$B$7,G27*'Parâmetros'!$B$6/30*MAX(0,I27-F27),0)-0.01),MAX(0,I27-F27),MAX(0,'Parâmetros'!$B$4-F27))) | K27: =IF(J27>'Parâmetros'!$B$7,ROUND(G27*'Parâmetros'!$B$5,2),0) | L27: =IF(J27>'Parâmetros'!$B$7,ROUND(G27*'Parâmetros'!$B$6/30*J27,2),0) | M27: =IF(F27>'Parâmetros'!$B$4,0,G27+K27+L27) | N27: =MAX(0,ROUND(M27-H27,2)) | O27: =IF(F27>'Parâmetros'!$B$4,"A vencer",IF(N27=0,IF(J27>'Parâmetros'!$B$7,"Pago com atraso","Pago"),IF(Q27<>"",Q27,IF(H27>0,"Parcial","Em atraso")))) | P27: =IF(F27>'Parâmetros'!$B$4,0,MIN(G27,H27)) | R27: =IF(N27=0,"",IF(J27<=30,"1 a 30 dias",IF(J27<=60,"31 a 60 dias",IF(J27<=90,"61 a 90 dias","Mais de 90 dias"))))
A28: C-24 | B28: CT-04 | C28: =INDEX(Contratos!$B$5:$B$9,MATCH(B28,Contratos!$A$5:$A$9,0)) | D28: =INDEX(Contratos!$C$5:$C$9,MATCH(B28,Contratos!$A$5:$A$9,0)) | E28: 46357 | F28: =DATE(YEAR(E28),MONTH(E28),INDEX(Contratos!$F$5:$F$9,MATCH(B28,Contratos!$A$5:$A$9,0))) | G28: =INDEX(Contratos!$E$5:$E$9,MATCH(B28,Contratos!$A$5:$A$9,0)) | H28: =SUMIFS(Recebimentos!$C$5:$C$200,Recebimentos!$B$5:$B$200,A28) | I28: =IF(H28=0,"",_xlfn.MAXIFS(Recebimentos!$A$5:$A$200,Recebimentos!$B$5:$B$200,A28)) | J28: =IF(F28>'Parâmetros'!$B$4,0,IF(IF(I28="",FALSE,H28>=G28*(1+IF(MAX(0,I28-F28)>'Parâmetros'!$B$7,'Parâmetros'!$B$5,0))+IF(MAX(0,I28-F28)>'Parâmetros'!$B$7,G28*'Parâmetros'!$B$6/30*MAX(0,I28-F28),0)-0.01),MAX(0,I28-F28),MAX(0,'Parâmetros'!$B$4-F28))) | K28: =IF(J28>'Parâmetros'!$B$7,ROUND(G28*'Parâmetros'!$B$5,2),0) | L28: =IF(J28>'Parâmetros'!$B$7,ROUND(G28*'Parâmetros'!$B$6/30*J28,2),0) | M28: =IF(F28>'Parâmetros'!$B$4,0,G28+K28+L28) | N28: =MAX(0,ROUND(M28-H28,2)) | O28: =IF(F28>'Parâmetros'!$B$4,"A vencer",IF(N28=0,IF(J28>'Parâmetros'!$B$7,"Pago com atraso","Pago"),IF(Q28<>"",Q28,IF(H28>0,"Parcial","Em atraso")))) | P28: =IF(F28>'Parâmetros'!$B$4,0,MIN(G28,H28)) | R28: =IF(N28=0,"",IF(J28<=30,"1 a 30 dias",IF(J28<=60,"31 a 60 dias",IF(J28<=90,"61 a 90 dias","Mais de 90 dias"))))
A29: C-25 | B29: CT-05 | C29: =INDEX(Contratos!$B$5:$B$9,MATCH(B29,Contratos!$A$5:$A$9,0)) | D29: =INDEX(Contratos!$C$5:$C$9,MATCH(B29,Contratos!$A$5:$A$9,0)) | E29: 46204 | F29: =DATE(YEAR(E29),MONTH(E29),INDEX(Contratos!$F$5:$F$9,MATCH(B29,Contratos!$A$5:$A$9,0))) | G29: =INDEX(Contratos!$E$5:$E$9,MATCH(B29,Contratos!$A$5:$A$9,0)) | H29: =SUMIFS(Recebimentos!$C$5:$C$200,Recebimentos!$B$5:$B$200,A29) | I29: =IF(H29=0,"",_xlfn.MAXIFS(Recebimentos!$A$5:$A$200,Recebimentos!$B$5:$B$200,A29)) | J29: =IF(F29>'Parâmetros'!$B$4,0,IF(IF(I29="",FALSE,H29>=G29*(1+IF(MAX(0,I29-F29)>'Parâmetros'!$B$7,'Parâmetros'!$B$5,0))+IF(MAX(0,I29-F29)>'Parâmetros'!$B$7,G29*'Parâmetros'!$B$6/30*MAX(0,I29-F29),0)-0.01),MAX(0,I29-F29),MAX(0,'Parâmetros'!$B$4-F29))) | K29: =IF(J29>'Parâmetros'!$B$7,ROUND(G29*'Parâmetros'!$B$5,2),0) | L29: =IF(J29>'Parâmetros'!$B$7,ROUND(G29*'Parâmetros'!$B$6/30*J29,2),0) | M29: =IF(F29>'Parâmetros'!$B$4,0,G29+K29+L29) | N29: =MAX(0,ROUND(M29-H29,2)) | O29: =IF(F29>'Parâmetros'!$B$4,"A vencer",IF(N29=0,IF(J29>'Parâmetros'!$B$7,"Pago com atraso","Pago"),IF(Q29<>"",Q29,IF(H29>0,"Parcial","Em atraso")))) | P29: =IF(F29>'Parâmetros'!$B$4,0,MIN(G29,H29)) | R29: =IF(N29=0,"",IF(J29<=30,"1 a 30 dias",IF(J29<=60,"31 a 60 dias",IF(J29<=90,"61 a 90 dias","Mais de 90 dias"))))
A30: C-26 | B30: CT-05 | C30: =INDEX(Contratos!$B$5:$B$9,MATCH(B30,Contratos!$A$5:$A$9,0)) | D30: =INDEX(Contratos!$C$5:$C$9,MATCH(B30,Contratos!$A$5:$A$9,0)) | E30: 46235 | F30: =DATE(YEAR(E30),MONTH(E30),INDEX(Contratos!$F$5:$F$9,MATCH(B30,Contratos!$A$5:$A$9,0))) | G30: =INDEX(Contratos!$E$5:$E$9,MATCH(B30,Contratos!$A$5:$A$9,0)) | H30: =SUMIFS(Recebimentos!$C$5:$C$200,Recebimentos!$B$5:$B$200,A30) | I30: =IF(H30=0,"",_xlfn.MAXIFS(Recebimentos!$A$5:$A$200,Recebimentos!$B$5:$B$200,A30)) | J30: =IF(F30>'Parâmetros'!$B$4,0,IF(IF(I30="",FALSE,H30>=G30*(1+IF(MAX(0,I30-F30)>'Parâmetros'!$B$7,'Parâmetros'!$B$5,0))+IF(MAX(0,I30-F30)>'Parâmetros'!$B$7,G30*'Parâmetros'!$B$6/30*MAX(0,I30-F30),0)-0.01),MAX(0,I30-F30),MAX(0,'Parâmetros'!$B$4-F30))) | K30: =IF(J30>'Parâmetros'!$B$7,ROUND(G30*'Parâmetros'!$B$5,2),0) | L30: =IF(J30>'Parâmetros'!$B$7,ROUND(G30*'Parâmetros'!$B$6/30*J30,2),0) | M30: =IF(F30>'Parâmetros'!$B$4,0,G30+K30+L30) | N30: =MAX(0,ROUND(M30-H30,2)) | O30: =IF(F30>'Parâmetros'!$B$4,"A vencer",IF(N30=0,IF(J30>'Parâmetros'!$B$7,"Pago com atraso","Pago"),IF(Q30<>"",Q30,IF(H30>0,"Parcial","Em atraso")))) | P30: =IF(F30>'Parâmetros'!$B$4,0,MIN(G30,H30)) | Q30: Cobrança judicial | R30: =IF(N30=0,"",IF(J30<=30,"1 a 30 dias",IF(J30<=60,"31 a 60 dias",IF(J30<=90,"61 a 90 dias","Mais de 90 dias")))) | S30: Ação de despejo por falta de pagamento ajuizada em 15/10/2026
A31: C-27 | B31: CT-05 | C31: =INDEX(Contratos!$B$5:$B$9,MATCH(B31,Contratos!$A$5:$A$9,0)) | D31: =INDEX(Contratos!$C$5:$C$9,MATCH(B31,Contratos!$A$5:$A$9,0)) | E31: 46266 | F31: =DATE(YEAR(E31),MONTH(E31),INDEX(Contratos!$F$5:$F$9,MATCH(B31,Contratos!$A$5:$A$9,0))) | G31: =INDEX(Contratos!$E$5:$E$9,MATCH(B31,Contratos!$A$5:$A$9,0)) | H31: =SUMIFS(Recebimentos!$C$5:$C$200,Recebimentos!$B$5:$B$200,A31) | I31: =IF(H31=0,"",_xlfn.MAXIFS(Recebimentos!$A$5:$A$200,Recebimentos!$B$5:$B$200,A31)) | J31: =IF(F31>'Parâmetros'!$B$4,0,IF(IF(I31="",FALSE,H31>=G31*(1+IF(MAX(0,I31-F31)>'Parâmetros'!$B$7,'Parâmetros'!$B$5,0))+IF(MAX(0,I31-F31)>'Parâmetros'!$B$7,G31*'Parâmetros'!$B$6/30*MAX(0,I31-F31),0)-0.01),MAX(0,I31-F31),MAX(0,'Parâmetros'!$B$4-F31))) | K31: =IF(J31>'Parâmetros'!$B$7,ROUND(G31*'Parâmetros'!$B$5,2),0) | L31: =IF(J31>'Parâmetros'!$B$7,ROUND(G31*'Parâmetros'!$B$6/30*J31,2),0) | M31: =IF(F31>'Parâmetros'!$B$4,0,G31+K31+L31) | N31: =MAX(0,ROUND(M31-H31,2)) | O31: =IF(F31>'Parâmetros'!$B$4,"A vencer",IF(N31=0,IF(J31>'Parâmetros'!$B$7,"Pago com atraso","Pago"),IF(Q31<>"",Q31,IF(H31>0,"Parcial","Em atraso")))) | P31: =IF(F31>'Parâmetros'!$B$4,0,MIN(G31,H31)) | Q31: Cobrança judicial | R31: =IF(N31=0,"",IF(J31<=30,"1 a 30 dias",IF(J31<=60,"31 a 60 dias",IF(J31<=90,"61 a 90 dias","Mais de 90 dias")))) | S31: Incluída na ação de despejo
A32: C-28 | B32: CT-05 | C32: =INDEX(Contratos!$B$5:$B$9,MATCH(B32,Contratos!$A$5:$A$9,0)) | D32: =INDEX(Contratos!$C$5:$C$9,MATCH(B32,Contratos!$A$5:$A$9,0)) | E32: 46296 | F32: =DATE(YEAR(E32),MONTH(E32),INDEX(Contratos!$F$5:$F$9,MATCH(B32,Contratos!$A$5:$A$9,0))) | G32: =INDEX(Contratos!$E$5:$E$9,MATCH(B32,Contratos!$A$5:$A$9,0)) | H32: =SUMIFS(Recebimentos!$C$5:$C$200,Recebimentos!$B$5:$B$200,A32) | I32: =IF(H32=0,"",_xlfn.MAXIFS(Recebimentos!$A$5:$A$200,Recebimentos!$B$5:$B$200,A32)) | J32: =IF(F32>'Parâmetros'!$B$4,0,IF(IF(I32="",FALSE,H32>=G32*(1+IF(MAX(0,I32-F32)>'Parâmetros'!$B$7,'Parâmetros'!$B$5,0))+IF(MAX(0,I32-F32)>'Parâmetros'!$B$7,G32*'Parâmetros'!$B$6/30*MAX(0,I32-F32),0)-0.01),MAX(0,I32-F32),MAX(0,'Parâmetros'!$B$4-F32))) | K32: =IF(J32>'Parâmetros'!$B$7,ROUND(G32*'Parâmetros'!$B$5,2),0) | L32: =IF(J32>'Parâmetros'!$B$7,ROUND(G32*'Parâmetros'!$B$6/30*J32,2),0) | M32: =IF(F32>'Parâmetros'!$B$4,0,G32+K32+L32) | N32: =MAX(0,ROUND(M32-H32,2)) | O32: =IF(F32>'Parâmetros'!$B$4,"A vencer",IF(N32=0,IF(J32>'Parâmetros'!$B$7,"Pago com atraso","Pago"),IF(Q32<>"",Q32,IF(H32>0,"Parcial","Em atraso")))) | P32: =IF(F32>'Parâmetros'!$B$4,0,MIN(G32,H32)) | Q32: Cobrança judicial | R32: =IF(N32=0,"",IF(J32<=30,"1 a 30 dias",IF(J32<=60,"31 a 60 dias",IF(J32<=90,"61 a 90 dias","Mais de 90 dias")))) | S32: Incluída na ação de despejo
A33: C-29 | B33: CT-05 | C33: =INDEX(Contratos!$B$5:$B$9,MATCH(B33,Contratos!$A$5:$A$9,0)) | D33: =INDEX(Contratos!$C$5:$C$9,MATCH(B33,Contratos!$A$5:$A$9,0)) | E33: 46327 | F33: =DATE(YEAR(E33),MONTH(E33),INDEX(Contratos!$F$5:$F$9,MATCH(B33,Contratos!$A$5:$A$9,0))) | G33: =INDEX(Contratos!$E$5:$E$9,MATCH(B33,Contratos!$A$5:$A$9,0)) | H33: =SUMIFS(Recebimentos!$C$5:$C$200,Recebimentos!$B$5:$B$200,A33) | I33: =IF(H33=0,"",_xlfn.MAXIFS(Recebimentos!$A$5:$A$200,Recebimentos!$B$5:$B$200,A33)) | J33: =IF(F33>'Parâmetros'!$B$4,0,IF(IF(I33="",FALSE,H33>=G33*(1+IF(MAX(0,I33-F33)>'Parâmetros'!$B$7,'Parâmetros'!$B$5,0))+IF(MAX(0,I33-F33)>'Parâmetros'!$B$7,G33*'Parâmetros'!$B$6/30*MAX(0,I33-F33),0)-0.01),MAX(0,I33-F33),MAX(0,'Parâmetros'!$B$4-F33))) | K33: =IF(J33>'Parâmetros'!$B$7,ROUND(G33*'Parâmetros'!$B$5,2),0) | L33: =IF(J33>'Parâmetros'!$B$7,ROUND(G33*'Parâmetros'!$B$6/30*J33,2),0) | M33: =IF(F33>'Parâmetros'!$B$4,0,G33+K33+L33) | N33: =MAX(0,ROUND(M33-H33,2)) | O33: =IF(F33>'Parâmetros'!$B$4,"A vencer",IF(N33=0,IF(J33>'Parâmetros'!$B$7,"Pago com atraso","Pago"),IF(Q33<>"",Q33,IF(H33>0,"Parcial","Em atraso")))) | P33: =IF(F33>'Parâmetros'!$B$4,0,MIN(G33,H33)) | R33: =IF(N33=0,"",IF(J33<=30,"1 a 30 dias",IF(J33<=60,"31 a 60 dias",IF(J33<=90,"61 a 90 dias","Mais de 90 dias"))))
A34: C-30 | B34: CT-05 | C34: =INDEX(Contratos!$B$5:$B$9,MATCH(B34,Contratos!$A$5:$A$9,0)) | D34: =INDEX(Contratos!$C$5:$C$9,MATCH(B34,Contratos!$A$5:$A$9,0)) | E34: 46357 | F34: =DATE(YEAR(E34),MONTH(E34),INDEX(Contratos!$F$5:$F$9,MATCH(B34,Contratos!$A$5:$A$9,0))) | G34: =INDEX(Contratos!$E$5:$E$9,MATCH(B34,Contratos!$A$5:$A$9,0)) | H34: =SUMIFS(Recebimentos!$C$5:$C$200,Recebimentos!$B$5:$B$200,A34) | I34: =IF(H34=0,"",_xlfn.MAXIFS(Recebimentos!$A$5:$A$200,Recebimentos!$B$5:$B$200,A34)) | J34: =IF(F34>'Parâmetros'!$B$4,0,IF(IF(I34="",FALSE,H34>=G34*(1+IF(MAX(0,I34-F34)>'Parâmetros'!$B$7,'Parâmetros'!$B$5,0))+IF(MAX(0,I34-F34)>'Parâmetros'!$B$7,G34*'Parâmetros'!$B$6/30*MAX(0,I34-F34),0)-0.01),MAX(0,I34-F34),MAX(0,'Parâmetros'!$B$4-F34))) | K34: =IF(J34>'Parâmetros'!$B$7,ROUND(G34*'Parâmetros'!$B$5,2),0) | L34: =IF(J34>'Parâmetros'!$B$7,ROUND(G34*'Parâmetros'!$B$6/30*J34,2),0) | M34: =IF(F34>'Parâmetros'!$B$4,0,G34+K34+L34) | N34: =MAX(0,ROUND(M34-H34,2)) | O34: =IF(F34>'Parâmetros'!$B$4,"A vencer",IF(N34=0,IF(J34>'Parâmetros'!$B$7,"Pago com atraso","Pago"),IF(Q34<>"",Q34,IF(H34>0,"Parcial","Em atraso")))) | P34: =IF(F34>'Parâmetros'!$B$4,0,MIN(G34,H34)) | R34: =IF(N34=0,"",IF(J34<=30,"1 a 30 dias",IF(J34<=60,"31 a 60 dias",IF(J34<=90,"61 a 90 dias","Mais de 90 dias"))))

Sheet Contratos
A1: Contratos de locação
A2: Valor do aluguel, vencimento, índice de reajuste e garantia.
A4: Contrato | B4: Imóvel | C4: Inquilino | D4: Início | E4: Aluguel (R$) | F4: Dia do vencimento | G4: Índice de reajuste | H4: Garantia | I4: Próximo reajuste | J4: Dias até o reajuste
A5: CT-01 | B5: I01 | C5: Marina L. | D5: 45976 | E5: 2800 | F5: 5 | G5: IGP-M | H5: Seguro fiança | I5: =DATE(YEAR('Parâmetros'!$B$4)+IF(DATE(YEAR('Parâmetros'!$B$4),MONTH(D5),DAY(D5))<='Parâmetros'!$B$4,1,0),MONTH(D5),DAY(D5)) | J5: =I5-'Parâmetros'!$B$4
A6: CT-02 | B6: I02 | C6: Pedro R. | D6: 45352 | E6: 3500 | F6: 5 | G6: IPCA | H6: Fiador | I6: =DATE(YEAR('Parâmetros'!$B$4)+IF(DATE(YEAR('Parâmetros'!$B$4),MONTH(D6),DAY(D6))<='Parâmetros'!$B$4,1,0),MONTH(D6),DAY(D6)) | J6: =I6-'Parâmetros'!$B$4
A7: CT-03 | B7: I03 | C7: Lucas F. ME | D7: 46032 | E7: 1900 | F7: 10 | G7: IGP-M | H7: Caução (3 aluguéis) | I7: =DATE(YEAR('Parâmetros'!$B$4)+IF(DATE(YEAR('Parâmetros'!$B$4),MONTH(D7),DAY(D7))<='Parâmetros'!$B$4,1,0),MONTH(D7),DAY(D7)) | J7: =I7-'Parâmetros'!$B$4
A8: CT-04 | B8: I04 | C8: Juliana T. | D8: 45996 | E8: 4200 | F8: 5 | G8: IPCA | H8: Seguro fiança | I8: =DATE(YEAR('Parâmetros'!$B$4)+IF(DATE(YEAR('Parâmetros'!$B$4),MONTH(D8),DAY(D8))<='Parâmetros'!$B$4,1,0),MONTH(D8),DAY(D8)) | J8: =I8-'Parâmetros'!$B$4
A9: CT-05 | B9: I05 | C9: Rafael G. | D9: 45809 | E9: 2300 | F9: 5 | G9: IGP-M | H9: Fiador | I9: =DATE(YEAR('Parâmetros'!$B$4)+IF(DATE(YEAR('Parâmetros'!$B$4),MONTH(D9),DAY(D9))<='Parâmetros'!$B$4,1,0),MONTH(D9),DAY(D9)) | J9: =I9-'Parâmetros'!$B$4

Sheet Imóveis
A1: Imóveis
A2: Curitiba - PR. Endereços fictícios.
A4: Imóvel | B4: Endereço | C4: Bairro | D4: Tipo | E4: Contrato
A5: I01 | B5: Rua Exemplo A, 100, ap. 32 | C5: Batel | D5: Apartamento | E5: =IFERROR(INDEX(Contratos!$A$5:$A$9,MATCH(A5,Contratos!$B$5:$B$9,0)),"Vago")
A6: I02 | B6: Rua Exemplo B, 250 | C6: Água Verde | D6: Casa | E6: =IFERROR(INDEX(Contratos!$A$5:$A$9,MATCH(A6,Contratos!$B$5:$B$9,0)),"Vago")
A7: I03 | B7: Rua Exemplo C, 45, sala 4 | C7: Centro | D7: Sala comercial | E7: =IFERROR(INDEX(Contratos!$A$5:$A$9,MATCH(A7,Contratos!$B$5:$B$9,0)),"Vago")
A8: I04 | B8: Rua Exemplo D, 780, ap. 101 | C8: Bigorrilho | D8: Apartamento | E8: =IFERROR(INDEX(Contratos!$A$5:$A$9,MATCH(A8,Contratos!$B$5:$B$9,0)),"Vago")
A9: I05 | B9: Rua Exemplo E, 15 | C9: Portão | D9: Casa | E9: =IFERROR(INDEX(Contratos!$A$5:$A$9,MATCH(A9,Contratos!$B$5:$B$9,0)),"Vago")

Sheet Despesas
A1: Despesas do proprietário
A2: Pagas pela administradora e descontadas no repasse.
A4: Data | B4: Imóvel | C4: Descrição | D4: Valor (R$)
A5: 46223 | B5: I04 | C5: Seguro incêndio anual | D5: 380
A6: 46246 | B6: I02 | C6: Reparo hidráulico | D6: 450
A7: 46283 | B7: I03 | C7: Pintura da fachada (parte do proprietário) | D7: 1200

Sheet Cobrança judicial
A1: Custos da cobrança judicial
A2: Custas, honorários e diligências de cada processo. Os pagos pelo proprietário são descontados no repasse.
A4: Data | B4: Imóvel | C4: Contrato | D4: Descrição | E4: Valor (R$) | F4: Pago por | G4: Reembolsável pelo inquilino?
A5: 46310 | B5: I05 | C5: =IFERROR(INDEX(Contratos!$A$5:$A$9,MATCH(B5,Contratos!$B$5:$B$9,0)),"") | D5: Custas iniciais da ação de despejo por falta de pagamento | E5: 480 | F5: Proprietário | G5: Sim
A6: 46310 | B6: I05 | C6: =IFERROR(INDEX(Contratos!$A$5:$A$9,MATCH(B6,Contratos!$B$5:$B$9,0)),"") | D6: Honorários advocatícios contratuais (entrada) | E6: 1500 | F6: Proprietário | G6: Não
A7: 46317 | B7: I05 | C7: =IFERROR(INDEX(Contratos!$A$5:$A$9,MATCH(B7,Contratos!$B$5:$B$9,0)),"") | D7: Diligência do oficial de justiça (citação) | E7: 95 | F7: Proprietário | G7: Sim
D9: Total | E9: =SUM(E5:E8)
D10: Reembolsável pelo inquilino (pedir na ação) | E10: =SUMIFS(E5:E8,G5:G8,"Sim")
A12: Os valores reembolsáveis dependem da decisão judicial e do contrato; confirme com o advogado responsável.

Sheet Proprietários
A1: Proprietários e participação
A2: Percentual de cada proprietário em cada imóvel. O líquido segue a participação.
H3: Participação (%)
A4: Proprietário | B4: Participação por imóvel | D4: Líquido acumulado (R$) | E4: Já repassado (R$) | F4: A repassar (R$) | H4: I01 | I4: I02 | J4: I03 | K4: I04 | L4: I05
A5: Ana P. | B5: =TEXT(H5,"0%")&" / "&TEXT(I5,"0%")&" / "&TEXT(J5,"0%")&" / "&TEXT(K5,"0%")&" / "&TEXT(L5,"0%") | D5: =SUMPRODUCT(H5:L5,$H$11:$L$11) | E5: =SUMIFS(Repasses!$C$5:$C$200,Repasses!$B$5:$B$200,A5) | F5: =ROUND(D5-E5,2) | H5: 1 | I5: 0.5 | J5: 0 | K5: 0 | L5: 1
A6: Bruno S. | B6: =TEXT(H6,"0%")&" / "&TEXT(I6,"0%")&" / "&TEXT(J6,"0%")&" / "&TEXT(K6,"0%")&" / "&TEXT(L6,"0%") | D6: =SUMPRODUCT(H6:L6,$H$11:$L$11) | E6: =SUMIFS(Repasses!$C$5:$C$200,Repasses!$B$5:$B$200,A6) | F6: =ROUND(D6-E6,2) | H6: 0 | I6: 0.5 | J6: 0 | K6: 0.6 | L6: 0
A7: Carlos M. | B7: =TEXT(H7,"0%")&" / "&TEXT(I7,"0%")&" / "&TEXT(J7,"0%")&" / "&TEXT(K7,"0%")&" / "&TEXT(L7,"0%") | D7: =SUMPRODUCT(H7:L7,$H$11:$L$11) | E7: =SUMIFS(Repasses!$C$5:$C$200,Repasses!$B$5:$B$200,A7) | F7: =ROUND(D7-E7,2) | H7: 0 | I7: 0 | J7: 1 | K7: 0.4 | L7: 0
A8: Soma da participação (deve ser 100%) | H8: =SUM(H5:H7) | I8: =SUM(I5:I7) | J8: =SUM(J5:J7) | K8: =SUM(K5:K7) | L8: =SUM(L5:L7)
A9: Total | D9: =SUM(D5:D7) | E9: =SUM(E5:E7) | F9: =SUM(F5:F7)
G11: Líquido por imóvel | H11: =Painel!I19 | I11: =Painel!I20 | J11: =Painel!I21 | K11: =Painel!I22 | L11: =Painel!I23

Sheet Repasses
A1: Repasses feitos
A2: Lance cada transferência feita ao proprietário.
A4: Data | B4: Proprietário | C4: Valor (R$) | D4: Referência
A5: 46249 | B5: Ana P. | C5: 6165 | D5: Repasse de 07/2026
A6: 46249 | B6: Bruno S. | C6: 3615 | D6: Repasse de 07/2026
A7: 46249 | B7: Carlos M. | C7: 3070 | D7: Repasse de 07/2026
A8: 46280 | B8: Ana P. | C8: 3870 | D8: Repasse de 08/2026
A9: 46280 | B9: Bruno S. | C9: 3618 | D9: Repasse de 08/2026
A10: 46280 | B10: Carlos M. | C10: 3222 | D10: Repasse de 08/2026
